<?xml version="1.0" ?>
<!-- =================================================================================== -->
<!-- |    This document was autogenerated by xacro from hyqreal.urdf.xacro             | -->
<!-- |    EDITING THIS FILE BY HAND IS NOT RECOMMENDED                                 | -->
<!-- =================================================================================== -->
<robot name="hyqreal" xmlns:xacro="http://ros.org/wiki/xacro">
  <!-- standard distances -->
  <!-- <xacro:property name="d_lr" value="0.414"/>
	<xacro:property name="d_fh" value="0.747"/> -->
  <!-- 0.887 1.4192-->
  <gazebo>
    <plugin filename="libgazebo_ros_control.so" name="gazebo_ros_controller_manager">
      <robotNamespace>/hyqreal</robotNamespace>
      <robotSimType>dls_gazebo_interface/DlsRobotHwSim</robotSimType>
      <controlPeriod>0.004</controlPeriod>
    </plugin>
    <plugin filename="libgazebo_ros_p3d.so" name="gazebo_ros_p3d">
      <robotNamespace>/hyqreal</robotNamespace>
      <bodyName>trunk</bodyName>
      <topicName>ground_truth</topicName>
      <frameName>world</frameName>
      <xyzOffsets>0 0 0</xyzOffsets>
      <rpyOffsets>0 0 0</rpyOffsets>
      <gaussianNoise>0</gaussianNoise>
      <alwaysOn>true</alwaysOn>
      <updateRate>250.0</updateRate>
    </plugin>
  </gazebo>
  <!-- Now we can start using the macros included above to define the actual hyqreal -->
  <!-- The first use of a macro. This one was defined in trunk.urdf.xacro above.
A macro like this will expand to a set of link and joint definitions, and to additional
Gazebo-related extensions (sensor plugins, etc). The macro takes an argument, name,
that equals "base", and uses it to generate names for its component links and joints
(e.g., base_link). The included origin block is also an argument to the macro. By convention,
the origin block defines where the component is w.r.t its parent (in this case the parent
is the world frame). For more, see http://www.ros.org/wiki/xacro -->
  <!-- Floating-base Joint -->
  <joint name="floating_base" type="fixed">
    <origin rpy="0 0 0" xyz="0 0 0"/>
    <parent link="base_link"/>
    <child link="trunk"/>
  </joint>
  <!-- Links -->
  <!-- Footprint link -->
  <link name="base_link">
    <visual>
      <geometry>
        <cylinder length="0.01" radius="0.01"/>
      </geometry>
    </visual>
  </link>
  <!-- Trunk link -->
  <link name="trunk">
    <inertial>
      <origin xyz="0.0149 -0.00186 -0.03465"/>
      <mass value="59.8"/>
      <inertia ixx="1.498728" ixy="-0.007369" ixz="-0.189135" iyy="9.492381" iyz="0.000185" izz="9.012359"/>
    </inertial>
    <visual>
      <origin rpy="0 0 3.14159265359" xyz="0 0 0"/>
      <geometry>
        <mesh filename="package://hyqreal_description/meshes/trunk/combined_torso.dae" scale="0.001 0.001 0.001"/>
      </geometry>
    </visual>
    <collision>
      <origin rpy="0 0 3.14159265359" xyz="0 0 0"/>
      <geometry>
        <mesh filename="package://hyqreal_description/meshes/trunk/combined_torso_decimated.dae" scale="0.001 0.001 0.001"/>
      </geometry>
    </collision>
  </link>
  <gazebo reference="trunk">
    <kp>100000000.0</kp>
    <kd>100.0</kd>
    <mu1>1.5</mu1>
    <mu2>1.5</mu2>
    <maxVel>1.0</maxVel>
    <maxContacts>10</maxContacts>
    <minDepth>0.00</minDepth>
  </gazebo>
  <sensor name="trunk_contact_sensor" type="contact">
    <always_on>true</always_on>
    <update_rate>100.0</update_rate>
    <contact>
      <collision>trunk_collision</collision>
    </contact>
    <plugin filename="libgazebo_ros_bumper.so" name="trunk_bumper">
      <bumperTopicName>/trunk_sensor</bumperTopicName>
      <frameName>base_link</frameName>
    </plugin>
  </sensor>
  <!-- Joints -->
  <!-- HAA joint -->
  <joint name="lf_haa_joint" type="revolute">
    <origin rpy="3.14159265359 1.57079632679 0" xyz="0.4435 0.139 0"/>
    <parent link="trunk"/>
    <child link="lf_hipassembly"/>
    <axis xyz="0 0 1"/>
    <dynamics damping="0.1" friction="0"/>
    <limit effort="173.0" lower="-0.733038285838" upper="0.401425727959" velocity="12.0"/>
    <safety_controller k_position="50" k_velocity="10" soft_lower_limit="-0.733038285838" soft_upper_limit="0.401425727959"/>
  </joint>
  <!-- HFE joint -->
  <joint name="lf_hfe_joint" type="revolute">
    <origin rpy="1.57079632679 0 0" xyz="0 -0.117 0"/>
    <parent link="lf_hipassembly"/>
    <child link="lf_upperleg"/>
    <axis xyz="0 0 1"/>
    <dynamics damping="0.1" friction="0"/>
    <limit effort="208" lower="-2.35619449019" upper="2.35619449019" velocity="12.0"/>
    <safety_controller k_position="50" k_velocity="10" soft_lower_limit="-2.35619449019" soft_upper_limit="2.35619449019"/>
  </joint>
  <!-- KFE joint -->
  <joint name="lf_kfe_joint" type="revolute">
    <origin rpy="0 0 0" xyz="0.36 0 0"/>
    <parent link="lf_upperleg"/>
    <child link="lf_lowerleg"/>
    <axis xyz="0 0 1"/>
    <dynamics damping="0.1" friction="0"/>
    <limit effort="249" lower="-2.77001205584" upper="-0.669857366915" velocity="12.0"/>
    <safety_controller k_position="50.0" k_velocity="10.0" soft_lower_limit="-2.77001205584" soft_upper_limit="-0.669857366915"/>
  </joint>
  <!-- Foot joint -->
  <joint name="lf_foot_joint" type="fixed">
    <origin rpy="1.57079632679 0 -1.57079632679" xyz="0.38 0 0"/>
    <parent link="lf_lowerleg"/>
    <child link="lf_foot"/>
  </joint>
  <!-- Links -->
  <!-- Hip assembly link -->
  <link name="lf_hipassembly">
    <inertial>
      <origin xyz="-0.010027 -0.010608 0.003644"/>
      <mass value="4.973275"/>
      <inertia ixx="0.011231" ixy="-0.000592" ixz="0.000225" iyy="0.015768" iyz="0.000224" izz="0.016863"/>
    </inertial>
    <visual>
      <origin rpy="0 -1.57079632679 -1.57079632679" xyz="0 -0.046 0"/>
      <geometry>
         --&gt;
				
        <cylinder length="0.117" radius="0.0444"/>
      </geometry>
    </visual>
  </link>
  <!-- Upper leg link -->
  <link name="lf_upperleg">
    <inertial>
      <origin xyz="0.107987 -0.011459 -0.002121"/>
      <mass value="5.877927"/>
      <inertia ixx="0.016432" ixy="0.001863" ixz="0.003897" iyy="0.075737" iyz="-0.00024" izz="0.079267"/>
    </inertial>
    <visual>
      <origin rpy="0 0 0" xyz="0 0 0"/>
      <geometry>
        <mesh filename="package://hyqreal_description/meshes/leg/upperleg.dae" scale="0.001 0.001 0.001"/>
      </geometry>
    </visual>
    <collision>
      <origin rpy="0 0 0" xyz="0 0 0"/>
      <geometry>
        <mesh filename="package://hyqreal_description/meshes/leg/upperleg.dae" scale="0.001 0.001 0.001"/>
      </geometry>
    </collision>
  </link>
  <!-- Lower leg link -->
  <link name="lf_lowerleg">
    <inertial>
      <origin xyz="0.149302 -0.003801 -0.000624"/>
      <mass value="1.291954"/>
      <inertia ixx="0.001088" ixy="-0.000572" ixz="0.000118" iyy="0.029215" iyz="0.00046" izz="0.029772"/>
    </inertial>
    <visual>
      <origin rpy="0 0 0" xyz="0 0 0"/>
      <geometry>
        <mesh filename="package://hyqreal_description/meshes/leg/lowerleg.dae" scale="0.001 0.001 0.001"/>
      </geometry>
      <material name="white"/>
    </visual>
    <collision>
      <origin rpy="0 0 0" xyz="0 0 0"/>
      <geometry>
        <mesh filename="package://hyqreal_description/meshes/leg/lowerleg_decimated.dae" scale="0.001 0.001 0.001"/>
      </geometry>
    </collision>
  </link>
  <!-- Foot link -->
  <link name="lf_foot">
    <visual>
      <origin rpy="0.0 0.0 0.0" xyz="0.0 0.0 0.0"/>
      <geometry>
        <sphere radius="0.032"/>
      </geometry>
      <material name="black"/>
    </visual>
    <collision>
      <origin rpy="0 0 0" xyz="0 0 0"/>
      <geometry>
        <sphere radius="0.032"/>
      </geometry>
    </collision>
  </link>
  <!-- Hip assembly -->
  <transmission name="lf_haa_trans">
    <type>transmission_interface/SimpleTransmission</type>
    <joint name="lf_haa_joint">
      <hardwareInterface>EffortJointInterface</hardwareInterface>
    </joint>
    <actuator name="lf_haa_motor">
      <hardwareInterface>EffortJointInterface</hardwareInterface>
      <mechanicalReduction>1</mechanicalReduction>
    </actuator>
  </transmission>
  <!-- Upper leg -->
  <transmission name="lf_hfe_trans">
    <type>transmission_interface/SimpleTransmission</type>
    <joint name="lf_hfe_joint">
      <hardwareInterface>EffortJointInterface</hardwareInterface>
    </joint>
    <actuator name="lf_hfe_motor">
      <hardwareInterface>EffortJointInterface</hardwareInterface>
      <mechanicalReduction>1</mechanicalReduction>
    </actuator>
  </transmission>
  <!-- Lower leg -->
  <transmission name="lf_kfe_trans">
    <type>transmission_interface/SimpleTransmission</type>
    <joint name="lf_kfe_joint">
      <hardwareInterface>EffortJointInterface</hardwareInterface>
    </joint>
    <actuator name="lf_kfe_motor">
      <hardwareInterface>EffortJointInterface</hardwareInterface>
      <mechanicalReduction>1</mechanicalReduction>
    </actuator>
  </transmission>
  <gazebo reference="lf_haa_joint">
    <provideFeedback>true</provideFeedback>
  </gazebo>
  <gazebo reference="lf_kfe_joint">
    <provideFeedback>true</provideFeedback>
  </gazebo>
  <gazebo reference="lf_hfe_joint">
    <provideFeedback>true</provideFeedback>
  </gazebo>
  <gazebo reference="lf_upperleg">
    <kp>100000000.0</kp>
    <kd>100.0</kd>
    <mu1>1.5</mu1>
    <mu2>1.5</mu2>
    <maxVel>1.0</maxVel>
    <minDepth>0.00</minDepth>
  </gazebo>
  <gazebo reference="lf_lowerleg">
    <kp>100000000.0</kp>
    <kd>100.0</kd>
    <mu1>1.5</mu1>
    <mu2>1.5</mu2>
    <maxVel>1.0</maxVel>
    <maxContacts>1</maxContacts>
    <minDepth>0.00</minDepth>
    <sensor name="lf_shin_contact_sensor" type="contact">
      <always_on>true</always_on>
      <update_rate>250.0</update_rate>
      <contact>
        <collision>lf_lowerleg_collision</collision>
      </contact>
      <plugin filename="libgazebo_ros_bumper.so" name="lf_shin_bumper">
        <bumperTopicName>/lf_shin_sensor</bumperTopicName>
      </plugin>
    </sensor>
  </gazebo>
  <gazebo reference="lf_foot">
    <kp>1000000.0</kp>
    <kd>100.0</kd>
    <mu1>1.0</mu1>
    <mu2>1.0</mu2>
    <maxVel>1.0</maxVel>
    <maxContacts>1</maxContacts>
    <!-- contact sensor -->
    <sensor name="lf_foot_contact_sensor" type="contact">
      <always_on>true</always_on>
      <update_rate>250.0</update_rate>
      <contact>
        <collision>lf_foot_collision</collision>
      </contact>
      <plugin filename="libgazebo_ros_bumper.so" name="lf_foot_bumper">
        <bumperTopicName>/lf_foot_grf</bumperTopicName>
        <frameName>base_link</frameName>
      </plugin>
    </sensor>
    <material>Gazebo/Black</material>
  </gazebo>
  <!-- Joints -->
  <!-- HAA joint -->
  <joint name="rf_haa_joint" type="revolute">
    <origin rpy="0 1.57079632679 0" xyz="0.4435 -0.139 0"/>
    <parent link="trunk"/>
    <child link="rf_hipassembly"/>
    <axis xyz="0 0 1"/>
    <dynamics damping="0.1" friction="0"/>
    <limit effort="173.0" lower="-0.733038285838" upper="0.401425727959" velocity="12.0"/>
    <safety_controller k_position="50" k_velocity="10" soft_lower_limit="-0.733038285838" soft_upper_limit="0.401425727959"/>
  </joint>
  <!-- HFE joint -->
  <joint name="rf_hfe_joint" type="revolute">
    <origin rpy="-1.57079632679 0 0" xyz="0 -0.117 0"/>
    <parent link="rf_hipassembly"/>
    <child link="rf_upperleg"/>
    <axis xyz="0 0 1"/>
    <dynamics damping="0.1" friction="0"/>
    <limit effort="208" lower="-2.35619449019" upper="2.35619449019" velocity="12.0"/>
    <safety_controller k_position="50" k_velocity="10" soft_lower_limit="-2.35619449019" soft_upper_limit="2.35619449019"/>
  </joint>
  <!-- KFE joint -->
  <joint name="rf_kfe_joint" type="revolute">
    <origin rpy="0 0 0" xyz="0.36 0 0"/>
    <parent link="rf_upperleg"/>
    <child link="rf_lowerleg"/>
    <axis xyz="0 0 1"/>
    <dynamics damping="0.1" friction="0"/>
    <limit effort="249" lower="-2.77001205584" upper="-0.669857366915" velocity="12.0"/>
    <safety_controller k_position="50.0" k_velocity="10.0" soft_lower_limit="-2.77001205584" soft_upper_limit="-0.669857366915"/>
  </joint>
  <!-- Foot joint -->
  <joint name="rf_foot_joint" type="fixed">
    <origin rpy="1.57079632679 0 -1.57079632679" xyz="0.38 0 0"/>
    <parent link="rf_lowerleg"/>
    <child link="rf_foot"/>
  </joint>
  <!-- Links -->
  <!-- Hip assembly link -->
  <link name="rf_hipassembly">
    <inertial>
      <origin xyz="-0.010027 -0.010608 0.003644"/>
      <mass value="4.973275"/>
      <inertia ixx="0.011231" ixy="-0.000592" ixz="0.000225" iyy="0.015768" iyz="0.000224" izz="0.016863"/>
    </inertial>
    <visual>
      <origin rpy="0 -1.57079632679 -1.57079632679" xyz="0 -0.046 0"/>
      <geometry>
         --&gt;
				
        <cylinder length="0.117" radius="0.0444"/>
      </geometry>
    </visual>
  </link>
  <!-- Upper leg link -->
  <link name="rf_upperleg">
    <inertial>
      <origin xyz="0.107987 -0.011459 0.002121"/>
      <mass value="5.877927"/>
      <inertia ixx="0.016432" ixy="0.001863" ixz="-0.003897" iyy="0.075737" iyz="0.00024" izz="0.079267"/>
    </inertial>
    <visual>
      <origin rpy="0 0 0" xyz="0 0 0"/>
      <geometry>
        <mesh filename="package://hyqreal_description/meshes/leg/upperleg.dae" scale="0.001 0.001 0.001"/>
      </geometry>
    </visual>
    <collision>
      <origin rpy="0 0 0" xyz="0 0 0"/>
      <geometry>
        <mesh filename="package://hyqreal_description/meshes/leg/upperleg.dae" scale="0.001 0.001 0.001"/>
      </geometry>
    </collision>
  </link>
  <!-- Lower leg link -->
  <link name="rf_lowerleg">
    <inertial>
      <origin xyz="0.149302 -0.003801 -0.000624"/>
      <mass value="1.291954"/>
      <inertia ixx="0.001088" ixy="-0.000572" ixz="0.000118" iyy="0.029215" iyz="0.00046" izz="0.029772"/>
    </inertial>
    <visual>
      <origin rpy="0 0 0" xyz="0 0 0"/>
      <geometry>
        <mesh filename="package://hyqreal_description/meshes/leg/lowerleg.dae" scale="0.001 0.001 0.001"/>
      </geometry>
      <material name="white"/>
    </visual>
    <collision>
      <origin rpy="0 0 0" xyz="0 0 0"/>
      <geometry>
        <mesh filename="package://hyqreal_description/meshes/leg/lowerleg_decimated.dae" scale="0.001 0.001 0.001"/>
      </geometry>
    </collision>
  </link>
  <!-- Foot link -->
  <link name="rf_foot">
    <visual>
      <origin rpy="0.0 0.0 0.0" xyz="0.0 0.0 0.0"/>
      <geometry>
        <sphere radius="0.032"/>
      </geometry>
      <material name="black"/>
    </visual>
    <collision>
      <origin rpy="0 0 0" xyz="0 0 0"/>
      <geometry>
        <sphere radius="0.032"/>
      </geometry>
    </collision>
  </link>
  <!-- Hip assembly -->
  <transmission name="rf_haa_trans">
    <type>transmission_interface/SimpleTransmission</type>
    <joint name="rf_haa_joint">
      <hardwareInterface>EffortJointInterface</hardwareInterface>
    </joint>
    <actuator name="rf_haa_motor">
      <hardwareInterface>EffortJointInterface</hardwareInterface>
      <mechanicalReduction>1</mechanicalReduction>
    </actuator>
  </transmission>
  <!-- Upper leg -->
  <transmission name="rf_hfe_trans">
    <type>transmission_interface/SimpleTransmission</type>
    <joint name="rf_hfe_joint">
      <hardwareInterface>EffortJointInterface</hardwareInterface>
    </joint>
    <actuator name="rf_hfe_motor">
      <hardwareInterface>EffortJointInterface</hardwareInterface>
      <mechanicalReduction>1</mechanicalReduction>
    </actuator>
  </transmission>
  <!-- Lower leg -->
  <transmission name="rf_kfe_trans">
    <type>transmission_interface/SimpleTransmission</type>
    <joint name="rf_kfe_joint">
      <hardwareInterface>EffortJointInterface</hardwareInterface>
    </joint>
    <actuator name="rf_kfe_motor">
      <hardwareInterface>EffortJointInterface</hardwareInterface>
      <mechanicalReduction>1</mechanicalReduction>
    </actuator>
  </transmission>
  <gazebo reference="rf_haa_joint">
    <provideFeedback>true</provideFeedback>
  </gazebo>
  <gazebo reference="rf_kfe_joint">
    <provideFeedback>true</provideFeedback>
  </gazebo>
  <gazebo reference="rf_hfe_joint">
    <provideFeedback>true</provideFeedback>
  </gazebo>
  <gazebo reference="rf_upperleg">
    <kp>100000000.0</kp>
    <kd>100.0</kd>
    <mu1>1.5</mu1>
    <mu2>1.5</mu2>
    <maxVel>1.0</maxVel>
    <minDepth>0.00</minDepth>
  </gazebo>
  <gazebo reference="rf_lowerleg">
    <kp>100000000.0</kp>
    <kd>100.0</kd>
    <mu1>1.5</mu1>
    <mu2>1.5</mu2>
    <maxVel>1.0</maxVel>
    <maxContacts>1</maxContacts>
    <minDepth>0.00</minDepth>
    <sensor name="rf_shin_contact_sensor" type="contact">
      <always_on>true</always_on>
      <update_rate>250.0</update_rate>
      <contact>
        <collision>rf_lowerleg_collision</collision>
      </contact>
      <plugin filename="libgazebo_ros_bumper.so" name="rf_shin_bumper">
        <bumperTopicName>/rf_shin_sensor</bumperTopicName>
      </plugin>
    </sensor>
  </gazebo>
  <gazebo reference="rf_foot">
    <kp>1000000.0</kp>
    <kd>100.0</kd>
    <mu1>1.0</mu1>
    <mu2>1.0</mu2>
    <maxVel>1.0</maxVel>
    <maxContacts>1</maxContacts>
    <!-- contact sensor -->
    <sensor name="rf_foot_contact_sensor" type="contact">
      <always_on>true</always_on>
      <update_rate>250.0</update_rate>
      <contact>
        <collision>rf_foot_collision</collision>
      </contact>
      <plugin filename="libgazebo_ros_bumper.so" name="rf_foot_bumper">
        <bumperTopicName>/rf_foot_grf</bumperTopicName>
        <frameName>base_link</frameName>
      </plugin>
    </sensor>
    <material>Gazebo/Black</material>
  </gazebo>
  <!-- Joints -->
  <!-- HAA joint -->
  <joint name="lh_haa_joint" type="revolute">
    <origin rpy="3.14159265359 1.57079632679 0" xyz="-0.4435 0.139 0"/>
    <parent link="trunk"/>
    <child link="lh_hipassembly"/>
    <axis xyz="0 0 1"/>
    <dynamics damping="0.1" friction="0"/>
    <limit effort="173.0" lower="-0.733038285838" upper="0.401425727959" velocity="12.0"/>
    <safety_controller k_position="50" k_velocity="10" soft_lower_limit="-0.733038285838" soft_upper_limit="0.401425727959"/>
  </joint>
  <!-- HFE joint -->
  <joint name="lh_hfe_joint" type="revolute">
    <origin rpy="1.57079632679 0 0" xyz="0 -0.117 0"/>
    <parent link="lh_hipassembly"/>
    <child link="lh_upperleg"/>
    <axis xyz="0 0 1"/>
    <dynamics damping="0.1" friction="0"/>
    <limit effort="208" lower="-2.35619449019" upper="2.35619449019" velocity="12.0"/>
    <safety_controller k_position="50" k_velocity="10" soft_lower_limit="-2.35619449019" soft_upper_limit="2.35619449019"/>
  </joint>
  <!-- KFE joint -->
  <joint name="lh_kfe_joint" type="revolute">
    <origin rpy="0 0 0" xyz="0.36 0 0"/>
    <parent link="lh_upperleg"/>
    <child link="lh_lowerleg"/>
    <axis xyz="0 0 1"/>
    <dynamics damping="0.1" friction="0"/>
    <limit effort="249" lower="-2.77001205584" upper="-0.669857366915" velocity="12.0"/>
    <safety_controller k_position="50.0" k_velocity="10.0" soft_lower_limit="-2.77001205584" soft_upper_limit="-0.669857366915"/>
  </joint>
  <!-- Foot joint -->
  <joint name="lh_foot_joint" type="fixed">
    <origin rpy="1.57079632679 0 -1.57079632679" xyz="0.38 0 0"/>
    <parent link="lh_lowerleg"/>
    <child link="lh_foot"/>
  </joint>
  <!-- Links -->
  <!-- Hip assembly link -->
  <link name="lh_hipassembly">
    <inertial>
      <origin xyz="-0.010027 -0.010608 0.003644"/>
      <mass value="4.973275"/>
      <inertia ixx="0.011231" ixy="-0.000592" ixz="0.000225" iyy="0.015768" iyz="0.000224" izz="0.016863"/>
    </inertial>
    <visual>
      <origin rpy="0 -1.57079632679 -1.57079632679" xyz="0 -0.046 0"/>
      <geometry>
         --&gt;
				
        <cylinder length="0.117" radius="0.0444"/>
      </geometry>
    </visual>
  </link>
  <!-- Upper leg link -->
  <link name="lh_upperleg">
    <inertial>
      <origin xyz="0.107987 -0.011459 -0.002121"/>
      <mass value="5.877927"/>
      <inertia ixx="0.016432" ixy="0.001863" ixz="0.003897" iyy="0.075737" iyz="-0.00024" izz="0.079267"/>
    </inertial>
    <visual>
      <origin rpy="0 0 0" xyz="0 0 0"/>
      <geometry>
        <mesh filename="package://hyqreal_description/meshes/leg/upperleg.dae" scale="0.001 0.001 0.001"/>
      </geometry>
    </visual>
    <collision>
      <origin rpy="0 0 0" xyz="0 0 0"/>
      <geometry>
        <mesh filename="package://hyqreal_description/meshes/leg/upperleg.dae" scale="0.001 0.001 0.001"/>
      </geometry>
    </collision>
  </link>
  <!-- Lower leg link -->
  <link name="lh_lowerleg">
    <inertial>
      <origin xyz="0.149302 -0.003801 -0.000624"/>
      <mass value="1.291954"/>
      <inertia ixx="0.001088" ixy="-0.000572" ixz="0.000118" iyy="0.029215" iyz="0.00046" izz="0.029772"/>
    </inertial>
    <visual>
      <origin rpy="0 0 0" xyz="0 0 0"/>
      <geometry>
        <mesh filename="package://hyqreal_description/meshes/leg/lowerleg.dae" scale="0.001 0.001 0.001"/>
      </geometry>
      <material name="white"/>
    </visual>
    <collision>
      <origin rpy="0 0 0" xyz="0 0 0"/>
      <geometry>
        <mesh filename="package://hyqreal_description/meshes/leg/lowerleg_decimated.dae" scale="0.001 0.001 0.001"/>
      </geometry>
    </collision>
  </link>
  <!-- Foot link -->
  <link name="lh_foot">
    <visual>
      <origin rpy="0.0 0.0 0.0" xyz="0.0 0.0 0.0"/>
      <geometry>
        <sphere radius="0.032"/>
      </geometry>
      <material name="black"/>
    </visual>
    <collision>
      <origin rpy="0 0 0" xyz="0 0 0"/>
      <geometry>
        <sphere radius="0.032"/>
      </geometry>
    </collision>
  </link>
  <!-- Hip assembly -->
  <transmission name="lh_haa_trans">
    <type>transmission_interface/SimpleTransmission</type>
    <joint name="lh_haa_joint">
      <hardwareInterface>EffortJointInterface</hardwareInterface>
    </joint>
    <actuator name="lh_haa_motor">
      <hardwareInterface>EffortJointInterface</hardwareInterface>
      <mechanicalReduction>1</mechanicalReduction>
    </actuator>
  </transmission>
  <!-- Upper leg -->
  <transmission name="lh_hfe_trans">
    <type>transmission_interface/SimpleTransmission</type>
    <joint name="lh_hfe_joint">
      <hardwareInterface>EffortJointInterface</hardwareInterface>
    </joint>
    <actuator name="lh_hfe_motor">
      <hardwareInterface>EffortJointInterface</hardwareInterface>
      <mechanicalReduction>1</mechanicalReduction>
    </actuator>
  </transmission>
  <!-- Lower leg -->
  <transmission name="lh_kfe_trans">
    <type>transmission_interface/SimpleTransmission</type>
    <joint name="lh_kfe_joint">
      <hardwareInterface>EffortJointInterface</hardwareInterface>
    </joint>
    <actuator name="lh_kfe_motor">
      <hardwareInterface>EffortJointInterface</hardwareInterface>
      <mechanicalReduction>1</mechanicalReduction>
    </actuator>
  </transmission>
  <gazebo reference="lh_haa_joint">
    <provideFeedback>true</provideFeedback>
  </gazebo>
  <gazebo reference="lh_kfe_joint">
    <provideFeedback>true</provideFeedback>
  </gazebo>
  <gazebo reference="lh_hfe_joint">
    <provideFeedback>true</provideFeedback>
  </gazebo>
  <gazebo reference="lh_upperleg">
    <kp>100000000.0</kp>
    <kd>100.0</kd>
    <mu1>1.5</mu1>
    <mu2>1.5</mu2>
    <maxVel>1.0</maxVel>
    <minDepth>0.00</minDepth>
  </gazebo>
  <gazebo reference="lh_lowerleg">
    <kp>100000000.0</kp>
    <kd>100.0</kd>
    <mu1>1.5</mu1>
    <mu2>1.5</mu2>
    <maxVel>1.0</maxVel>
    <maxContacts>1</maxContacts>
    <minDepth>0.00</minDepth>
    <sensor name="lh_shin_contact_sensor" type="contact">
      <always_on>true</always_on>
      <update_rate>250.0</update_rate>
      <contact>
        <collision>lh_lowerleg_collision</collision>
      </contact>
      <plugin filename="libgazebo_ros_bumper.so" name="lh_shin_bumper">
        <bumperTopicName>/lh_shin_sensor</bumperTopicName>
      </plugin>
    </sensor>
  </gazebo>
  <gazebo reference="lh_foot">
    <kp>1000000.0</kp>
    <kd>100.0</kd>
    <mu1>1.0</mu1>
    <mu2>1.0</mu2>
    <maxVel>1.0</maxVel>
    <maxContacts>1</maxContacts>
    <!-- contact sensor -->
    <sensor name="lh_foot_contact_sensor" type="contact">
      <always_on>true</always_on>
      <update_rate>250.0</update_rate>
      <contact>
        <collision>lh_foot_collision</collision>
      </contact>
      <plugin filename="libgazebo_ros_bumper.so" name="lh_foot_bumper">
        <bumperTopicName>/lh_foot_grf</bumperTopicName>
        <frameName>base_link</frameName>
      </plugin>
    </sensor>
    <material>Gazebo/Black</material>
  </gazebo>
  <!-- Joints -->
  <!-- HAA joint -->
  <joint name="rh_haa_joint" type="revolute">
    <origin rpy="0 1.57079632679 0" xyz="-0.4435 -0.139 0"/>
    <parent link="trunk"/>
    <child link="rh_hipassembly"/>
    <axis xyz="0 0 1"/>
    <dynamics damping="0.1" friction="0"/>
    <limit effort="173.0" lower="-0.733038285838" upper="0.401425727959" velocity="12.0"/>
    <safety_controller k_position="50" k_velocity="10" soft_lower_limit="-0.733038285838" soft_upper_limit="0.401425727959"/>
  </joint>
  <!-- HFE joint -->
  <joint name="rh_hfe_joint" type="revolute">
    <origin rpy="-1.57079632679 0 0" xyz="0 -0.117 0"/>
    <parent link="rh_hipassembly"/>
    <child link="rh_upperleg"/>
    <axis xyz="0 0 1"/>
    <dynamics damping="0.1" friction="0"/>
    <limit effort="208" lower="-2.35619449019" upper="2.35619449019" velocity="12.0"/>
    <safety_controller k_position="50" k_velocity="10" soft_lower_limit="-2.35619449019" soft_upper_limit="2.35619449019"/>
  </joint>
  <!-- KFE joint -->
  <joint name="rh_kfe_joint" type="revolute">
    <origin rpy="0 0 0" xyz="0.36 0 0"/>
    <parent link="rh_upperleg"/>
    <child link="rh_lowerleg"/>
    <axis xyz="0 0 1"/>
    <dynamics damping="0.1" friction="0"/>
    <limit effort="249" lower="-2.77001205584" upper="-0.669857366915" velocity="12.0"/>
    <safety_controller k_position="50.0" k_velocity="10.0" soft_lower_limit="-2.77001205584" soft_upper_limit="-0.669857366915"/>
  </joint>
  <!-- Foot joint -->
  <joint name="rh_foot_joint" type="fixed">
    <origin rpy="1.57079632679 0 -1.57079632679" xyz="0.38 0 0"/>
    <parent link="rh_lowerleg"/>
    <child link="rh_foot"/>
  </joint>
  <!-- Links -->
  <!-- Hip assembly link -->
  <link name="rh_hipassembly">
    <inertial>
      <origin xyz="-0.010027 -0.010608 0.003644"/>
      <mass value="4.973275"/>
      <inertia ixx="0.011231" ixy="-0.000592" ixz="0.000225" iyy="0.015768" iyz="0.000224" izz="0.016863"/>
    </inertial>
    <visual>
      <origin rpy="0 -1.57079632679 -1.57079632679" xyz="0 -0.046 0"/>
      <geometry>
         --&gt;
				
        <cylinder length="0.117" radius="0.0444"/>
      </geometry>
    </visual>
  </link>
  <!-- Upper leg link -->
  <link name="rh_upperleg">
    <inertial>
      <origin xyz="0.107987 -0.011459 0.002121"/>
      <mass value="5.877927"/>
      <inertia ixx="0.016432" ixy="0.001863" ixz="-0.003897" iyy="0.075737" iyz="0.00024" izz="0.079267"/>
    </inertial>
    <visual>
      <origin rpy="0 0 0" xyz="0 0 0"/>
      <geometry>
        <mesh filename="package://hyqreal_description/meshes/leg/upperleg.dae" scale="0.001 0.001 0.001"/>
      </geometry>
    </visual>
    <collision>
      <origin rpy="0 0 0" xyz="0 0 0"/>
      <geometry>
        <mesh filename="package://hyqreal_description/meshes/leg/upperleg.dae" scale="0.001 0.001 0.001"/>
      </geometry>
    </collision>
  </link>
  <!-- Lower leg link -->
  <link name="rh_lowerleg">
    <inertial>
      <origin xyz="0.149302 -0.003801 -0.000624"/>
      <mass value="1.291954"/>
      <inertia ixx="0.001088" ixy="-0.000572" ixz="0.000118" iyy="0.029215" iyz="0.00046" izz="0.029772"/>
    </inertial>
    <visual>
      <origin rpy="0 0 0" xyz="0 0 0"/>
      <geometry>
        <mesh filename="package://hyqreal_description/meshes/leg/lowerleg.dae" scale="0.001 0.001 0.001"/>
      </geometry>
      <material name="white"/>
    </visual>
    <collision>
      <origin rpy="0 0 0" xyz="0 0 0"/>
      <geometry>
        <mesh filename="package://hyqreal_description/meshes/leg/lowerleg_decimated.dae" scale="0.001 0.001 0.001"/>
      </geometry>
    </collision>
  </link>
  <!-- Foot link -->
  <link name="rh_foot">
    <visual>
      <origin rpy="0.0 0.0 0.0" xyz="0.0 0.0 0.0"/>
      <geometry>
        <sphere radius="0.032"/>
      </geometry>
      <material name="black"/>
    </visual>
    <collision>
      <origin rpy="0 0 0" xyz="0 0 0"/>
      <geometry>
        <sphere radius="0.032"/>
      </geometry>
    </collision>
  </link>
  <!-- Hip assembly -->
  <transmission name="rh_haa_trans">
    <type>transmission_interface/SimpleTransmission</type>
    <joint name="rh_haa_joint">
      <hardwareInterface>EffortJointInterface</hardwareInterface>
    </joint>
    <actuator name="rh_haa_motor">
      <hardwareInterface>EffortJointInterface</hardwareInterface>
      <mechanicalReduction>1</mechanicalReduction>
    </actuator>
  </transmission>
  <!-- Upper leg -->
  <transmission name="rh_hfe_trans">
    <type>transmission_interface/SimpleTransmission</type>
    <joint name="rh_hfe_joint">
      <hardwareInterface>EffortJointInterface</hardwareInterface>
    </joint>
    <actuator name="rh_hfe_motor">
      <hardwareInterface>EffortJointInterface</hardwareInterface>
      <mechanicalReduction>1</mechanicalReduction>
    </actuator>
  </transmission>
  <!-- Lower leg -->
  <transmission name="rh_kfe_trans">
    <type>transmission_interface/SimpleTransmission</type>
    <joint name="rh_kfe_joint">
      <hardwareInterface>EffortJointInterface</hardwareInterface>
    </joint>
    <actuator name="rh_kfe_motor">
      <hardwareInterface>EffortJointInterface</hardwareInterface>
      <mechanicalReduction>1</mechanicalReduction>
    </actuator>
  </transmission>
  <gazebo reference="rh_haa_joint">
    <provideFeedback>true</provideFeedback>
  </gazebo>
  <gazebo reference="rh_kfe_joint">
    <provideFeedback>true</provideFeedback>
  </gazebo>
  <gazebo reference="rh_hfe_joint">
    <provideFeedback>true</provideFeedback>
  </gazebo>
  <gazebo reference="rh_upperleg">
    <kp>100000000.0</kp>
    <kd>100.0</kd>
    <mu1>1.5</mu1>
    <mu2>1.5</mu2>
    <maxVel>1.0</maxVel>
    <minDepth>0.00</minDepth>
  </gazebo>
  <gazebo reference="rh_lowerleg">
    <kp>100000000.0</kp>
    <kd>100.0</kd>
    <mu1>1.5</mu1>
    <mu2>1.5</mu2>
    <maxVel>1.0</maxVel>
    <maxContacts>1</maxContacts>
    <minDepth>0.00</minDepth>
    <sensor name="rh_shin_contact_sensor" type="contact">
      <always_on>true</always_on>
      <update_rate>250.0</update_rate>
      <contact>
        <collision>rh_lowerleg_collision</collision>
      </contact>
      <plugin filename="libgazebo_ros_bumper.so" name="rh_shin_bumper">
        <bumperTopicName>/rh_shin_sensor</bumperTopicName>
      </plugin>
    </sensor>
  </gazebo>
  <gazebo reference="rh_foot">
    <kp>1000000.0</kp>
    <kd>100.0</kd>
    <mu1>1.0</mu1>
    <mu2>1.0</mu2>
    <maxVel>1.0</maxVel>
    <maxContacts>1</maxContacts>
    <!-- contact sensor -->
    <sensor name="rh_foot_contact_sensor" type="contact">
      <always_on>true</always_on>
      <update_rate>250.0</update_rate>
      <contact>
        <collision>rh_foot_collision</collision>
      </contact>
      <plugin filename="libgazebo_ros_bumper.so" name="rh_foot_bumper">
        <bumperTopicName>/rh_foot_grf</bumperTopicName>
        <frameName>base_link</frameName>
      </plugin>
    </sensor>
    <material>Gazebo/Black</material>
  </gazebo>
</robot>

