<?xml version="1.0"?>
<robot xmlns:xacro="http://ros.org/wiki/xacro">


	<!-- Things that are needed only for Gazebo (not the physical robot). These include sensor and controller plugin specifications -->
	<xacro:include filename="$(find hyqreal_description)/urdfs/trunk/trunk.gazebo.xacro"/>


	<!-- ================================ Trunk ================================ -->
	<!-- The xacro macro xacro:hyq_base contains: base and trunk -->
	<xacro:macro name="hyqreal_trunk" params="name">
		<!-- Floating-base Joint -->
                <link name="world"/>
                <joint name="floating_base_joint" type="floating">
                  <origin rpy="0 0 0" xyz="0 0 0"/>
                  <parent link="world"/>
                  <child link="base_link"/>
                </joint>
                <joint name="floating_base" type="fixed">
                  <origin rpy="0 0 0" xyz="0 0 0"/>
                  <parent link="base_link"/>
                  <child link="trunk"/>
                </joint>

		<!-- Links -->
		<!-- Footprint link -->
		<link name="${name}_link">
			<visual>
				<geometry>
					<cylinder length="0.01" radius="0.01"/>
				</geometry>
			</visual>
		</link>
		<!-- Trunk link -->
		<link name="trunk">
			<inertial>
				<origin xyz="${xcom_trunk} ${ycom_trunk} ${zcom_trunk}"/>
				<mass value="${m_trunk}"/>
				<inertia ixx="${ixx_trunk}" iyy="${iyy_trunk}" izz="${izz_trunk}"
						 ixy="${ixy_trunk}" ixz="${ixz_trunk}" iyz="${iyz_trunk}"/>
			</inertial>
			<visual>
				<origin xyz="0 0 0" rpy="0 0 ${PI}" />
				<geometry>
 					<mesh filename="package://hyqreal_description/meshes/trunk/combined_torso.dae" scale="0.001 0.001 0.001"/>
				</geometry>
			</visual>
			<collision>
				<origin xyz="0 0 0" rpy="0 0 ${PI}" />
				<geometry>
					<mesh filename="package://hyqreal_description/meshes/trunk/combined_torso_decimated.dae" scale="0.001 0.001 0.001"/>
				</geometry>
			</collision>
		</link>

		<!-- Extensions -->
		<xacro:trunk_gazebo name="trunk"/>
	</xacro:macro>

</robot>
