<?xml version="1.0" ?>
<!-- =================================================================================== -->
<!-- |    This document was autogenerated by xacro from hyqreal-teleop.urdf.xacro      | -->
<!-- |    EDITING THIS FILE BY HAND IS NOT RECOMMENDED                                 | -->
<!-- =================================================================================== -->
<robot name="hyqreal_teleop" xmlns:xacro="http://ros.org/wiki/xacro">
  <!-- 
  ROS urdf definition of the TELEOP robot by Istituto Italiano di Tecnologia
  
  DO NOT INCLUDE THIS FILE DIRECTLY! USE teleop_robot.urdf.xacro INSTEAD!

  Author: Enrico Mingo

  Inertial matrix has to be in CoM frame (URDF specs)
-->
  <!-- 
  ROS urdf definition of the HYQREAL-TELEOP robot by Istituto Italiano di Tecnologia
  
  DO NOT INCLUDE THIS FILE DIRECTLY! USE teleop_robot.urdf.xacro INSTEAD!

  Author: Enrico Mingo Hoffman

  Inertial matrix has to be in CoM frame (URDF specs)

-->
  <!-- standard distances -->
  <!-- <xacro:property name="d_lr" value="0.414"/>
	<xacro:property name="d_fh" value="0.747"/> -->
  <!-- 0.887 1.4192-->
  <link name="world"/>
  <joint name="floating_base_joint" type="floating">
    <origin rpy="0 0 0" xyz="0 0 0"/>
    <parent link="world"/>
    <child link="base_link"/>
  </joint>
  <link name="base_link"/>
  <joint name="bl_joint" type="fixed">
    <origin rpy="0 0 0" xyz="0 0 0"/>
    <parent link="base_link"/>
    <child link="trunk"/>
  </joint>
  <joint name="front_middle_realsense_d435_joint_x" type="fixed">
    <parent link="trunk"/>
    <child link="front_middle_realsense_d435_link"/>
    <origin rpy="0 0 0" xyz="0.6 0.05 0.22"/>
    <!--limit effort="0000.0" lower="-1.0" upper="1.0" velocity="0.0"/>
            <dynamics damping="10000000.0" friction="100000000.0"/>
            <axis xyz="0 0 1" /-->
  </joint>
  <!-- generate an optical frame 
            http://www.ros.org/reps/rep-0103.html#suffix-frames
            so that ros and opencv can operate on the camera frame correctly 
            -->
  <joint name="front_middle_camera_optical_joint" type="fixed">
    <!-- these values have to be these values otherwise the gazebo camera
            image won't be aligned properly with the frame it is supposedly
            originating from -->
    <origin rpy="-1.57079632679 0 -1.57079632679" xyz="0 0 0"/>
    <parent link="front_middle_realsense_d435_link"/>
    <child link="front_middle_realsense_d435_link_optical"/>
  </joint>
  <link name="front_middle_realsense_d435_link_optical">
        </link>
  <link name="front_middle_realsense_d435_link">
    <inertial>
      <mass value="0.1"/>
      <inertia ixx="100" ixy="0" ixz="0" iyy="100" iyz="0" izz="100"/>
    </inertial>
    <collision name="collision">
      <geometry>
        <box size="0.073000 0.276000 0.072000"/>
      </geometry>
    </collision>
    <visual name="visual">
      <geometry>
        <mesh filename="package://ur_description/meshes/cameras/realsense_d435/realsense_d435.dae"/>
      </geometry>
    </visual>
  </link>
  <gazebo reference="front_middle_realsense_d435_link">
    <sensor name="front_middle_camera" type="depth">
      <update_rate>40</update_rate>
      <camera>
        <horizontal_fov>1.487</horizontal_fov>
        <image>
          <width>848</width>
          <height>480</height>
          <format>R8G8B8</format>
        </image>
        <clip>
          <!-- The minimum depth for the realsense at 848x480 is about 16.8cm -->
          <near>0.168</near>
          <far>5</far>
        </clip>
      </camera>
      <plugin filename="libgazebo_ros_openni_kinect.so" name="camera_plugin">
        <baseline>0.2</baseline>
        <alwaysOn>true</alwaysOn>
        <!-- Keep this zero, update_rate in the parent <sensor> tag
                      will control the frame rate. -->
        <updateRate>0.0</updateRate>
        <cameraName>front_middle_realsense_d435</cameraName>
        <imageTopicName>/front_middle_realsense_d435/rgb/image_raw</imageTopicName>
        <cameraInfoTopicName>/front_middle_realsense_d435/rgb/camera_info</cameraInfoTopicName>
        <depthImageTopicName>/front_middle_realsense_d435/depth/image_raw</depthImageTopicName>
        <depthImageInfoTopicName>/front_middle_realsense_d435/depth/camera_info</depthImageInfoTopicName>
        <pointCloudTopicName>/front_middle_realsense_d435/depth/points</pointCloudTopicName>
        <frameName>front_middle_realsense_d435_link_optical</frameName>
        <pointCloudCutoff>0.05</pointCloudCutoff>
        <distortionK1>0</distortionK1>
        <distortionK2>0</distortionK2>
        <distortionK3>0</distortionK3>
        <distortionT1>0</distortionT1>
        <distortionT2>0</distortionT2>
        <CxPrime>0</CxPrime>
        <Cx>0</Cx>
        <Cy>0</Cy>
        <focalLength>0</focalLength>
        <hackBaseline>0</hackBaseline>
      </plugin>
    </sensor>
    <static>true</static>
  </gazebo>
  <joint name="front_right_zed_camera_joint_x" type="fixed">
    <parent link="trunk"/>
    <child link="front_right_zed_camera_center"/>
    <origin rpy="0 0 -0.585" xyz="0.6 -0.15 0.0"/>
  </joint>
  <!-- Camera Center -->
  <link name="front_right_zed_camera_center">
    <visual>
      <origin rpy="0 0 0" xyz="0 0 0"/>
      <geometry>
        <mesh filename="package://zed_wrapper/urdf/ZED.stl"/>
      </geometry>
      <material name="light_grey">
        <color rgba="0.8 0.8 0.8 0.8"/>
      </material>
    </visual>
  </link>
  <!-- Left Camera -->
  <joint name="front_right_zed_left_camera_joint" type="fixed">
    <parent link="front_right_zed_camera_center"/>
    <child link="front_right_zed_left_camera_frame"/>
    <origin rpy="0 0 0" xyz="0 0.06 0"/>
  </joint>
  <link name="front_right_zed_left_camera_frame"/>
  <joint name="front_right_zed_left_camera_optical_joint" type="fixed">
    <origin rpy="-1.57079632679 0.0 -1.57079632679" xyz="0 0 0"/>
    <parent link="front_right_zed_left_camera_frame"/>
    <child link="front_right_zed_left_camera_optical_frame"/>
  </joint>
  <link name="front_right_zed_left_camera_optical_frame"/>
  <!-- Right Camera -->
  <joint name="front_right_zed_right_camera_joint" type="fixed">
    <parent link="front_right_zed_camera_center"/>
    <child link="front_right_zed_right_camera_frame"/>
    <origin rpy="0 0 0" xyz="0 -0.06 0"/>
  </joint>
  <link name="front_right_zed_right_camera_frame"/>
  <joint name="front_right_zed_right_camera_optical_joint" type="fixed">
    <origin rpy="-1.57079632679 0.0 -1.57079632679" xyz="0 0 0"/>
    <parent link="front_right_zed_right_camera_frame"/>
    <child link="front_right_zed_right_camera_optical_frame"/>
  </joint>
  <link name="front_right_zed_right_camera_optical_frame"/>
  <!-- Depth Frame -->
  <joint name="front_right_zed_depth_camera_joint" type="fixed">
    <parent link="front_right_zed_camera_center"/>
    <child link="front_right_zed_depth_camera_frame"/>
    <origin rpy="0 0 0" xyz="0 0.0 0"/>
  </joint>
  <link name="front_right_zed_depth_camera_frame"/>
  <joint name="front_right_zed_depth_camera_optical_joint" type="fixed">
    <origin rpy="-1.57079632679 0.0 -1.57079632679" xyz="0 0 0"/>
    <parent link="front_right_zed_depth_camera_frame"/>
    <child link="front_right_zed_depth_camera_optical_frame"/>
  </joint>
  <link name="front_right_zed_depth_camera_optical_frame"/>
  <gazebo reference="front_right_zed_left_camera_frame">
    <sensor name="front_right_zed_left_camera" type="camera">
      <update_rate>60</update_rate>
      <camera>
        <horizontal_fov>1.571</horizontal_fov>
        <image>
          <width>1280</width>
          <height>720</height>
          <format>R8G8B8</format>
        </image>
        <clip>
          <near>0.02</near>
          <far>300</far>
        </clip>
      </camera>
      <plugin filename="libgazebo_ros_camera.so" name="camera_controller">
        <alwaysOn>true</alwaysOn>
        <updateRate>0.0</updateRate>
        <cameraName>front_right_zed_left_camera</cameraName>
        <imageTopicName>/front_right_zed_camera/left/image_raw</imageTopicName>
        <cameraInfoTopicName>/front_right_zed_camera/left/camera_info</cameraInfoTopicName>
        <frameName>front_right_zed_left_camera_optical_frame</frameName>
        <hackBaseline>0.0</hackBaseline>
        <distortionK1>0.0</distortionK1>
        <distortionK2>0.0</distortionK2>
        <distortionK3>0.0</distortionK3>
        <distortionT1>0.0</distortionT1>
        <distortionT2>0.0</distortionT2>
      </plugin>
    </sensor>
    <static>true</static>
  </gazebo>
  <gazebo reference="front_right_zed_right_camera_frame">
    <sensor name="front_right_zed_right_camera" type="camera">
      <update_rate>60</update_rate>
      <camera>
        <horizontal_fov>1.571</horizontal_fov>
        <image>
          <width>1280</width>
          <height>720</height>
          <format>R8G8B8</format>
        </image>
        <clip>
          <near>0.02</near>
          <far>300</far>
        </clip>
      </camera>
      <plugin filename="libgazebo_ros_camera.so" name="camera_controller">
        <alwaysOn>true</alwaysOn>
        <updateRate>0.0</updateRate>
        <cameraName>front_right_zed_right_camera</cameraName>
        <imageTopicName>/front_right_zed_camera/right/image_raw</imageTopicName>
        <cameraInfoTopicName>/front_right_zed_camera/right/camera_info</cameraInfoTopicName>
        <frameName>front_right_zed_right_camera_optical_frame</frameName>
        <hackBaseline>0.0</hackBaseline>
        <distortionK1>0.0</distortionK1>
        <distortionK2>0.0</distortionK2>
        <distortionK3>0.0</distortionK3>
        <distortionT1>0.0</distortionT1>
        <distortionT2>0.0</distortionT2>
      </plugin>
    </sensor>
    <static>true</static>
  </gazebo>
  <gazebo reference="front_right_zed_depth_camera_frame">
    <sensor name="front_right_zed_depth_camera" type="depth">
      <update_rate>60</update_rate>
      <camera>
        <horizontal_fov>1.571</horizontal_fov>
        <image>
          <width>1280</width>
          <height>720</height>
          <format>R8G8B8</format>
        </image>
        <clip>
          <near>0.5</near>
          <far>10</far>
        </clip>
      </camera>
      <plugin filename="libgazebo_ros_openni_kinect.so" name="camera_controller">
        <alwaysOn>true</alwaysOn>
        <updateRate>0.0</updateRate>
        <cameraName>front_right_zed_depth_camera</cameraName>
        <depthImageTopicName>/front_right_zed_camera/image_raw</depthImageTopicName>
        <depthImageInfoTopicName>/front_right_zed_camera/camera_info</depthImageInfoTopicName>
        <frameName>front_right_zed_depth_camera_optical_frame</frameName>
        <hackBaseline>0.0</hackBaseline>
        <distortionK1>0.0</distortionK1>
        <distortionK2>0.0</distortionK2>
        <distortionK3>0.0</distortionK3>
        <distortionT1>0.0</distortionT1>
        <distortionT2>0.0</distortionT2>
      </plugin>
    </sensor>
    <static>true</static>
  </gazebo>
  <joint name="front_left_zed_camera_joint_x" type="fixed">
    <parent link="trunk"/>
    <child link="front_left_zed_camera_center"/>
    <origin rpy="0 0 0.585" xyz="0.6 0.15 0.0"/>
  </joint>
  <!-- Camera Center -->
  <link name="front_left_zed_camera_center">
    <visual>
      <origin rpy="0 0 0" xyz="0 0 0"/>
      <geometry>
        <mesh filename="package://zed_wrapper/urdf/ZED.stl"/>
      </geometry>
      <material name="light_grey">
        <color rgba="0.8 0.8 0.8 0.8"/>
      </material>
    </visual>
  </link>
  <!-- Left Camera -->
  <joint name="front_left_zed_left_camera_joint" type="fixed">
    <parent link="front_left_zed_camera_center"/>
    <child link="front_left_zed_left_camera_frame"/>
    <origin rpy="0 0 0" xyz="0 0.06 0"/>
  </joint>
  <link name="front_left_zed_left_camera_frame"/>
  <joint name="front_left_zed_left_camera_optical_joint" type="fixed">
    <origin rpy="-1.57079632679 0.0 -1.57079632679" xyz="0 0 0"/>
    <parent link="front_left_zed_left_camera_frame"/>
    <child link="front_left_zed_left_camera_optical_frame"/>
  </joint>
  <link name="front_left_zed_left_camera_optical_frame"/>
  <!-- Right Camera -->
  <joint name="front_left_zed_right_camera_joint" type="fixed">
    <parent link="front_left_zed_camera_center"/>
    <child link="front_left_zed_right_camera_frame"/>
    <origin rpy="0 0 0" xyz="0 -0.06 0"/>
  </joint>
  <link name="front_left_zed_right_camera_frame"/>
  <joint name="front_left_zed_right_camera_optical_joint" type="fixed">
    <origin rpy="-1.57079632679 0.0 -1.57079632679" xyz="0 0 0"/>
    <parent link="front_left_zed_right_camera_frame"/>
    <child link="front_left_zed_right_camera_optical_frame"/>
  </joint>
  <link name="front_left_zed_right_camera_optical_frame"/>
  <!-- Depth Frame -->
  <joint name="front_left_zed_depth_camera_joint" type="fixed">
    <parent link="front_left_zed_camera_center"/>
    <child link="front_left_zed_depth_camera_frame"/>
    <origin rpy="0 0 0" xyz="0 0.0 0"/>
  </joint>
  <link name="front_left_zed_depth_camera_frame"/>
  <joint name="front_left_zed_depth_camera_optical_joint" type="fixed">
    <origin rpy="-1.57079632679 0.0 -1.57079632679" xyz="0 0 0"/>
    <parent link="front_left_zed_depth_camera_frame"/>
    <child link="front_left_zed_depth_camera_optical_frame"/>
  </joint>
  <link name="front_left_zed_depth_camera_optical_frame"/>
  <gazebo reference="front_left_zed_left_camera_frame">
    <sensor name="front_left_zed_left_camera" type="camera">
      <update_rate>60</update_rate>
      <camera>
        <horizontal_fov>1.571</horizontal_fov>
        <image>
          <width>1280</width>
          <height>720</height>
          <format>R8G8B8</format>
        </image>
        <clip>
          <near>0.02</near>
          <far>300</far>
        </clip>
      </camera>
      <plugin filename="libgazebo_ros_camera.so" name="camera_controller">
        <alwaysOn>true</alwaysOn>
        <updateRate>0.0</updateRate>
        <cameraName>front_left_zed_left_camera</cameraName>
        <imageTopicName>/front_left_zed_camera/left/image_raw</imageTopicName>
        <cameraInfoTopicName>/front_left_zed_camera/left/camera_info</cameraInfoTopicName>
        <frameName>front_left_zed_left_camera_optical_frame</frameName>
        <hackBaseline>0.0</hackBaseline>
        <distortionK1>0.0</distortionK1>
        <distortionK2>0.0</distortionK2>
        <distortionK3>0.0</distortionK3>
        <distortionT1>0.0</distortionT1>
        <distortionT2>0.0</distortionT2>
      </plugin>
    </sensor>
    <static>true</static>
  </gazebo>
  <gazebo reference="front_left_zed_right_camera_frame">
    <sensor name="front_left_zed_right_camera" type="camera">
      <update_rate>60</update_rate>
      <camera>
        <horizontal_fov>1.571</horizontal_fov>
        <image>
          <width>1280</width>
          <height>720</height>
          <format>R8G8B8</format>
        </image>
        <clip>
          <near>0.02</near>
          <far>300</far>
        </clip>
      </camera>
      <plugin filename="libgazebo_ros_camera.so" name="camera_controller">
        <alwaysOn>true</alwaysOn>
        <updateRate>0.0</updateRate>
        <cameraName>front_left_zed_right_camera</cameraName>
        <imageTopicName>/front_left_zed_camera/right/image_raw</imageTopicName>
        <cameraInfoTopicName>/front_left_zed_camera/right/camera_info</cameraInfoTopicName>
        <frameName>front_left_zed_right_camera_optical_frame</frameName>
        <hackBaseline>0.0</hackBaseline>
        <distortionK1>0.0</distortionK1>
        <distortionK2>0.0</distortionK2>
        <distortionK3>0.0</distortionK3>
        <distortionT1>0.0</distortionT1>
        <distortionT2>0.0</distortionT2>
      </plugin>
    </sensor>
    <static>true</static>
  </gazebo>
  <gazebo reference="front_left_zed_depth_camera_frame">
    <sensor name="front_left_zed_depth_camera" type="depth">
      <update_rate>60</update_rate>
      <camera>
        <horizontal_fov>1.571</horizontal_fov>
        <image>
          <width>1280</width>
          <height>720</height>
          <format>R8G8B8</format>
        </image>
        <clip>
          <near>0.5</near>
          <far>10</far>
        </clip>
      </camera>
      <plugin filename="libgazebo_ros_openni_kinect.so" name="camera_controller">
        <alwaysOn>true</alwaysOn>
        <updateRate>0.0</updateRate>
        <cameraName>front_left_zed_depth_camera</cameraName>
        <depthImageTopicName>/front_left_zed_camera/image_raw</depthImageTopicName>
        <depthImageInfoTopicName>/front_left_zed_camera/camera_info</depthImageInfoTopicName>
        <frameName>front_left_zed_depth_camera_optical_frame</frameName>
        <hackBaseline>0.0</hackBaseline>
        <distortionK1>0.0</distortionK1>
        <distortionK2>0.0</distortionK2>
        <distortionK3>0.0</distortionK3>
        <distortionT1>0.0</distortionT1>
        <distortionT2>0.0</distortionT2>
      </plugin>
    </sensor>
    <static>true</static>
  </gazebo>
  <joint name="rear_zed_camera_joint_x" type="fixed">
    <parent link="trunk"/>
    <child link="rear_zed_camera_center"/>
    <origin rpy="0 0 0" xyz="-0.2 0.0 0.3"/>
  </joint>
  <!-- Camera Center -->
  <link name="rear_zed_camera_center">
    <visual>
      <origin rpy="0 0 0" xyz="0 0 0"/>
      <geometry>
        <mesh filename="package://zed_wrapper/urdf/ZED.stl"/>
      </geometry>
      <material name="light_grey">
        <color rgba="0.8 0.8 0.8 0.8"/>
      </material>
    </visual>
  </link>
  <!-- Left Camera -->
  <joint name="rear_zed_left_camera_joint" type="fixed">
    <parent link="rear_zed_camera_center"/>
    <child link="rear_zed_left_camera_frame"/>
    <origin rpy="0 0 0" xyz="0 0.06 0"/>
  </joint>
  <link name="rear_zed_left_camera_frame"/>
  <joint name="rear_zed_left_camera_optical_joint" type="fixed">
    <origin rpy="-1.57079632679 0.0 -1.57079632679" xyz="0 0 0"/>
    <parent link="rear_zed_left_camera_frame"/>
    <child link="rear_zed_left_camera_optical_frame"/>
  </joint>
  <link name="rear_zed_left_camera_optical_frame"/>
  <!-- Right Camera -->
  <joint name="rear_zed_right_camera_joint" type="fixed">
    <parent link="rear_zed_camera_center"/>
    <child link="rear_zed_right_camera_frame"/>
    <origin rpy="0 0 0" xyz="0 -0.06 0"/>
  </joint>
  <link name="rear_zed_right_camera_frame"/>
  <joint name="rear_zed_right_camera_optical_joint" type="fixed">
    <origin rpy="-1.57079632679 0.0 -1.57079632679" xyz="0 0 0"/>
    <parent link="rear_zed_right_camera_frame"/>
    <child link="rear_zed_right_camera_optical_frame"/>
  </joint>
  <link name="rear_zed_right_camera_optical_frame"/>
  <!-- Depth Frame -->
  <joint name="rear_zed_depth_camera_joint" type="fixed">
    <parent link="rear_zed_camera_center"/>
    <child link="rear_zed_depth_camera_frame"/>
    <origin rpy="0 0 0" xyz="0 0.0 0"/>
  </joint>
  <link name="rear_zed_depth_camera_frame"/>
  <joint name="rear_zed_depth_camera_optical_joint" type="fixed">
    <origin rpy="-1.57079632679 0.0 -1.57079632679" xyz="0 0 0"/>
    <parent link="rear_zed_depth_camera_frame"/>
    <child link="rear_zed_depth_camera_optical_frame"/>
  </joint>
  <link name="rear_zed_depth_camera_optical_frame"/>
  <gazebo reference="rear_zed_left_camera_frame">
    <sensor name="rear_zed_left_camera" type="camera">
      <update_rate>60</update_rate>
      <camera>
        <horizontal_fov>1.571</horizontal_fov>
        <image>
          <width>1280</width>
          <height>720</height>
          <format>R8G8B8</format>
        </image>
        <clip>
          <near>0.02</near>
          <far>300</far>
        </clip>
      </camera>
      <plugin filename="libgazebo_ros_camera.so" name="camera_controller">
        <alwaysOn>true</alwaysOn>
        <updateRate>0.0</updateRate>
        <cameraName>rear_zed_left_camera</cameraName>
        <imageTopicName>/rear_zed_camera/left/image_raw</imageTopicName>
        <cameraInfoTopicName>/rear_zed_camera/left/camera_info</cameraInfoTopicName>
        <frameName>rear_zed_left_camera_optical_frame</frameName>
        <hackBaseline>0.0</hackBaseline>
        <distortionK1>0.0</distortionK1>
        <distortionK2>0.0</distortionK2>
        <distortionK3>0.0</distortionK3>
        <distortionT1>0.0</distortionT1>
        <distortionT2>0.0</distortionT2>
      </plugin>
    </sensor>
    <static>true</static>
  </gazebo>
  <gazebo reference="rear_zed_right_camera_frame">
    <sensor name="rear_zed_right_camera" type="camera">
      <update_rate>60</update_rate>
      <camera>
        <horizontal_fov>1.571</horizontal_fov>
        <image>
          <width>1280</width>
          <height>720</height>
          <format>R8G8B8</format>
        </image>
        <clip>
          <near>0.02</near>
          <far>300</far>
        </clip>
      </camera>
      <plugin filename="libgazebo_ros_camera.so" name="camera_controller">
        <alwaysOn>true</alwaysOn>
        <updateRate>0.0</updateRate>
        <cameraName>rear_zed_right_camera</cameraName>
        <imageTopicName>/rear_zed_camera/right/image_raw</imageTopicName>
        <cameraInfoTopicName>/rear_zed_camera/right/camera_info</cameraInfoTopicName>
        <frameName>rear_zed_right_camera_optical_frame</frameName>
        <hackBaseline>0.0</hackBaseline>
        <distortionK1>0.0</distortionK1>
        <distortionK2>0.0</distortionK2>
        <distortionK3>0.0</distortionK3>
        <distortionT1>0.0</distortionT1>
        <distortionT2>0.0</distortionT2>
      </plugin>
    </sensor>
    <static>true</static>
  </gazebo>
  <gazebo reference="rear_zed_depth_camera_frame">
    <sensor name="rear_zed_depth_camera" type="depth">
      <update_rate>60</update_rate>
      <camera>
        <horizontal_fov>1.571</horizontal_fov>
        <image>
          <width>1280</width>
          <height>720</height>
          <format>R8G8B8</format>
        </image>
        <clip>
          <near>0.5</near>
          <far>10</far>
        </clip>
      </camera>
      <plugin filename="libgazebo_ros_openni_kinect.so" name="camera_controller">
        <alwaysOn>true</alwaysOn>
        <updateRate>0.0</updateRate>
        <cameraName>rear_zed_depth_camera</cameraName>
        <depthImageTopicName>/rear_zed_camera/image_raw</depthImageTopicName>
        <depthImageInfoTopicName>/rear_zed_camera/camera_info</depthImageInfoTopicName>
        <frameName>rear_zed_depth_camera_optical_frame</frameName>
        <hackBaseline>0.0</hackBaseline>
        <distortionK1>0.0</distortionK1>
        <distortionK2>0.0</distortionK2>
        <distortionK3>0.0</distortionK3>
        <distortionT1>0.0</distortionT1>
        <distortionT2>0.0</distortionT2>
      </plugin>
    </sensor>
    <static>true</static>
  </gazebo>
  <!-- Trunk link -->
  <link name="trunk">
    <inertial>
      <origin xyz="0.04725 6.9e-05 -0.03465"/>
      <mass value="84.991171"/>
      <inertia ixx="1.498728" ixy="-0.007369" ixz="-0.189135" iyy="9.492381" iyz="0.000185" izz="9.012359"/>
    </inertial>
    <visual>
      <origin rpy="0 0 3.14159265359" xyz="0 0 0"/>
      <geometry>
        <mesh filename="package://hyqreal_description/meshes/trunk/combined_torso.dae" scale="0.001 0.001 0.001"/>
      </geometry>
    </visual>
    <collision>
      <origin rpy="0 0 3.14159265359" xyz="0 0 0"/>
      <geometry>
        <mesh filename="package://hyqreal_description/meshes/trunk/combined_torso_decimated.dae" scale="0.001 0.001 0.001"/>
      </geometry>
    </collision>
  </link>
  <!-- Joints -->
  <!-- HAA joint -->
  <joint name="lf_haa_joint" type="revolute">
    <origin rpy="3.14159265359 1.57079632679 0" xyz="0.4435 0.139 0"/>
    <parent link="trunk"/>
    <child link="lf_hipassembly"/>
    <axis xyz="0 0 1"/>
    <dynamics damping="0.1" friction="0"/>
    <limit effort="173.0" lower="-0.733038285838" upper="0.401425727959" velocity="12.0"/>
    <safety_controller k_position="50" k_velocity="10" soft_lower_limit="-0.733038285838" soft_upper_limit="0.401425727959"/>
  </joint>
  <!-- HFE joint -->
  <joint name="lf_hfe_joint" type="revolute">
    <origin rpy="1.57079632679 0 0" xyz="0 -0.117 0"/>
    <parent link="lf_hipassembly"/>
    <child link="lf_upperleg"/>
    <axis xyz="0 0 1"/>
    <dynamics damping="0.1" friction="0"/>
    <limit effort="208" lower="-2.35619449019" upper="2.35619449019" velocity="12.0"/>
    <safety_controller k_position="50" k_velocity="10" soft_lower_limit="-2.35619449019" soft_upper_limit="2.35619449019"/>
  </joint>
  <!-- KFE joint -->
  <joint name="lf_kfe_joint" type="revolute">
    <origin rpy="0 0 0" xyz="0.36 0 0"/>
    <parent link="lf_upperleg"/>
    <child link="lf_lowerleg"/>
    <axis xyz="0 0 1"/>
    <dynamics damping="0.1" friction="0"/>
    <limit effort="249" lower="-2.87979326579" upper="-0.558505360638" velocity="12.0"/>
    <safety_controller k_position="50.0" k_velocity="10.0" soft_lower_limit="-2.87979326579" soft_upper_limit="-0.558505360638"/>
  </joint>
  <!-- Foot joint -->
  <joint name="lf_foot_joint" type="fixed">
    <origin rpy="1.57079632679 0 -1.57079632679" xyz="0.38 0 0"/>
    <parent link="lf_lowerleg"/>
    <child link="lf_foot"/>
  </joint>
  <!-- Links -->
  <!-- Hip assembly link -->
  <link name="lf_hipassembly">
    <inertial>
      <origin xyz="-0.010027 -0.010608 0.003644"/>
      <mass value="4.973275"/>
      <inertia ixx="0.011231" ixy="-0.000592" ixz="0.000225" iyy="0.015768" iyz="0.000224" izz="0.016863"/>
    </inertial>
    <visual>
      <origin rpy="0 -1.57079632679 -1.57079632679" xyz="0 -0.046 0"/>
      <geometry>
         --&gt;
				
        <cylinder length="0.117" radius="0.0444"/>
      </geometry>
    </visual>
  </link>
  <!-- Upper leg link -->
  <link name="lf_upperleg">
    <inertial>
      <origin xyz="0.107987 -0.011459 -0.002121"/>
      <mass value="5.877927"/>
      <inertia ixx="0.016432" ixy="0.001863" ixz="0.003897" iyy="0.075737" iyz="-0.00024" izz="0.079267"/>
    </inertial>
    <visual>
      <origin rpy="0 0 0" xyz="0 0 0"/>
      <geometry>
        <mesh filename="package://hyqreal_description/meshes/leg/upperleg.dae" scale="0.001 0.001 0.001"/>
      </geometry>
    </visual>
    <collision>
      <origin rpy="0 0 0" xyz="0 0 0"/>
      <geometry>
        <mesh filename="package://hyqreal_description/meshes/leg/upperleg.dae" scale="0.001 0.001 0.001"/>
      </geometry>
    </collision>
  </link>
  <!-- Lower leg link -->
  <link name="lf_lowerleg">
    <inertial>
      <origin xyz="0.149302 -0.003801 -0.000624"/>
      <mass value="1.291954"/>
      <inertia ixx="0.001088" ixy="-0.000572" ixz="0.000118" iyy="0.029215" iyz="0.00046" izz="0.029772"/>
    </inertial>
    <visual>
      <origin rpy="0 0 0" xyz="0 0 0"/>
      <geometry>
        <mesh filename="package://hyqreal_description/meshes/leg/lowerleg.dae" scale="0.001 0.001 0.001"/>
      </geometry>
      <material name="white"/>
    </visual>
    <collision>
      <origin rpy="0 0 0" xyz="0 0 0"/>
      <geometry>
        <mesh filename="package://hyqreal_description/meshes/leg/lowerleg_decimated.dae" scale="0.001 0.001 0.001"/>
      </geometry>
    </collision>
  </link>
  <!-- Foot link -->
  <link name="lf_foot">
    <visual>
      <origin rpy="0.0 0.0 0.0" xyz="0.0 0.0 0.0"/>
      <geometry>
        <sphere radius="0.032"/>
      </geometry>
      <material name="black"/>
    </visual>
    <collision>
      <origin rpy="0 0 0" xyz="0 0 0"/>
      <geometry>
        <sphere radius="0.032"/>
      </geometry>
    </collision>
  </link>
  <!-- Hip assembly -->
  <transmission name="lf_haa_trans">
    <type>transmission_interface/SimpleTransmission</type>
    <joint name="lf_haa_joint">
      <hardwareInterface>EffortJointInterface</hardwareInterface>
    </joint>
    <actuator name="lf_haa_motor">
      <hardwareInterface>EffortJointInterface</hardwareInterface>
      <mechanicalReduction>1</mechanicalReduction>
    </actuator>
  </transmission>
  <!-- Upper leg -->
  <transmission name="lf_hfe_trans">
    <type>transmission_interface/SimpleTransmission</type>
    <joint name="lf_hfe_joint">
      <hardwareInterface>EffortJointInterface</hardwareInterface>
    </joint>
    <actuator name="lf_hfe_motor">
      <hardwareInterface>EffortJointInterface</hardwareInterface>
      <mechanicalReduction>1</mechanicalReduction>
    </actuator>
  </transmission>
  <!-- Lower leg -->
  <transmission name="lf_kfe_trans">
    <type>transmission_interface/SimpleTransmission</type>
    <joint name="lf_kfe_joint">
      <hardwareInterface>EffortJointInterface</hardwareInterface>
    </joint>
    <actuator name="lf_kfe_motor">
      <hardwareInterface>EffortJointInterface</hardwareInterface>
      <mechanicalReduction>1</mechanicalReduction>
    </actuator>
  </transmission>
  <gazebo reference="lf_haa_joint">
    <provideFeedback>true</provideFeedback>
  </gazebo>
  <gazebo reference="lf_kfe_joint">
    <provideFeedback>true</provideFeedback>
  </gazebo>
  <gazebo reference="lf_hfe_joint">
    <provideFeedback>true</provideFeedback>
  </gazebo>
  <gazebo reference="lf_upperleg">
    <kp>100000000.0</kp>
    <kd>100.0</kd>
    <mu1>1.5</mu1>
    <mu2>1.5</mu2>
    <maxVel>1.0</maxVel>
    <minDepth>0.00</minDepth>
  </gazebo>
  <gazebo reference="lf_lowerleg">
    <kp>100000000.0</kp>
    <kd>100.0</kd>
    <mu1>1.5</mu1>
    <mu2>1.5</mu2>
    <maxVel>1.0</maxVel>
    <maxContacts>1</maxContacts>
    <minDepth>0.00</minDepth>
    <sensor name="lf_shin_contact_sensor" type="contact">
      <always_on>true</always_on>
      <update_rate>250.0</update_rate>
      <contact>
        <collision>lf_lowerleg_collision</collision>
      </contact>
      <plugin filename="libgazebo_ros_bumper.so" name="lf_shin_bumper">
        <bumperTopicName>/lf_shin_sensor</bumperTopicName>
      </plugin>
    </sensor>
  </gazebo>
  <gazebo reference="lf_foot">
    <kp>1000000.0</kp>
    <kd>100.0</kd>
    <mu1>1.0</mu1>
    <mu2>1.0</mu2>
    <maxVel>1.0</maxVel>
    <maxContacts>1</maxContacts>
    <!-- contact sensor -->
    <sensor name="lf_foot_contact_sensor" type="contact">
      <always_on>true</always_on>
      <update_rate>250.0</update_rate>
      <contact>
        <collision>lf_foot_collision</collision>
      </contact>
      <plugin filename="libgazebo_ros_bumper.so" name="lf_foot_bumper">
        <bumperTopicName>/lf_foot_grf</bumperTopicName>
        <frameName>base_link</frameName>
      </plugin>
    </sensor>
    <material>Gazebo/Black</material>
  </gazebo>
  <!-- Joints -->
  <!-- HAA joint -->
  <joint name="rf_haa_joint" type="revolute">
    <origin rpy="0 1.57079632679 0" xyz="0.4435 -0.139 0"/>
    <parent link="trunk"/>
    <child link="rf_hipassembly"/>
    <axis xyz="0 0 1"/>
    <dynamics damping="0.1" friction="0"/>
    <limit effort="173.0" lower="-0.733038285838" upper="0.401425727959" velocity="12.0"/>
    <safety_controller k_position="50" k_velocity="10" soft_lower_limit="-0.733038285838" soft_upper_limit="0.401425727959"/>
  </joint>
  <!-- HFE joint -->
  <joint name="rf_hfe_joint" type="revolute">
    <origin rpy="-1.57079632679 0 0" xyz="0 -0.117 0"/>
    <parent link="rf_hipassembly"/>
    <child link="rf_upperleg"/>
    <axis xyz="0 0 1"/>
    <dynamics damping="0.1" friction="0"/>
    <limit effort="208" lower="-2.35619449019" upper="2.35619449019" velocity="12.0"/>
    <safety_controller k_position="50" k_velocity="10" soft_lower_limit="-2.35619449019" soft_upper_limit="2.35619449019"/>
  </joint>
  <!-- KFE joint -->
  <joint name="rf_kfe_joint" type="revolute">
    <origin rpy="0 0 0" xyz="0.36 0 0"/>
    <parent link="rf_upperleg"/>
    <child link="rf_lowerleg"/>
    <axis xyz="0 0 1"/>
    <dynamics damping="0.1" friction="0"/>
    <limit effort="249" lower="-2.87979326579" upper="-0.558505360638" velocity="12.0"/>
    <safety_controller k_position="50.0" k_velocity="10.0" soft_lower_limit="-2.87979326579" soft_upper_limit="-0.558505360638"/>
  </joint>
  <!-- Foot joint -->
  <joint name="rf_foot_joint" type="fixed">
    <origin rpy="1.57079632679 0 -1.57079632679" xyz="0.38 0 0"/>
    <parent link="rf_lowerleg"/>
    <child link="rf_foot"/>
  </joint>
  <!-- Links -->
  <!-- Hip assembly link -->
  <link name="rf_hipassembly">
    <inertial>
      <origin xyz="-0.010027 -0.010608 0.003644"/>
      <mass value="4.973275"/>
      <inertia ixx="0.011231" ixy="-0.000592" ixz="0.000225" iyy="0.015768" iyz="0.000224" izz="0.016863"/>
    </inertial>
    <visual>
      <origin rpy="0 -1.57079632679 -1.57079632679" xyz="0 -0.046 0"/>
      <geometry>
         --&gt;
				
        <cylinder length="0.117" radius="0.0444"/>
      </geometry>
    </visual>
  </link>
  <!-- Upper leg link -->
  <link name="rf_upperleg">
    <inertial>
      <origin xyz="0.107987 -0.011459 0.002121"/>
      <mass value="5.877927"/>
      <inertia ixx="0.016432" ixy="0.001863" ixz="-0.003897" iyy="0.075737" iyz="0.00024" izz="0.079267"/>
    </inertial>
    <visual>
      <origin rpy="0 0 0" xyz="0 0 0"/>
      <geometry>
        <mesh filename="package://hyqreal_description/meshes/leg/upperleg.dae" scale="0.001 0.001 0.001"/>
      </geometry>
    </visual>
    <collision>
      <origin rpy="0 0 0" xyz="0 0 0"/>
      <geometry>
        <mesh filename="package://hyqreal_description/meshes/leg/upperleg.dae" scale="0.001 0.001 0.001"/>
      </geometry>
    </collision>
  </link>
  <!-- Lower leg link -->
  <link name="rf_lowerleg">
    <inertial>
      <origin xyz="0.149302 -0.003801 -0.000624"/>
      <mass value="1.291954"/>
      <inertia ixx="0.001088" ixy="-0.000572" ixz="0.000118" iyy="0.029215" iyz="0.00046" izz="0.029772"/>
    </inertial>
    <visual>
      <origin rpy="0 0 0" xyz="0 0 0"/>
      <geometry>
        <mesh filename="package://hyqreal_description/meshes/leg/lowerleg.dae" scale="0.001 0.001 0.001"/>
      </geometry>
      <material name="white"/>
    </visual>
    <collision>
      <origin rpy="0 0 0" xyz="0 0 0"/>
      <geometry>
        <mesh filename="package://hyqreal_description/meshes/leg/lowerleg_decimated.dae" scale="0.001 0.001 0.001"/>
      </geometry>
    </collision>
  </link>
  <!-- Foot link -->
  <link name="rf_foot">
    <visual>
      <origin rpy="0.0 0.0 0.0" xyz="0.0 0.0 0.0"/>
      <geometry>
        <sphere radius="0.032"/>
      </geometry>
      <material name="black"/>
    </visual>
    <collision>
      <origin rpy="0 0 0" xyz="0 0 0"/>
      <geometry>
        <sphere radius="0.032"/>
      </geometry>
    </collision>
  </link>
  <!-- Hip assembly -->
  <transmission name="rf_haa_trans">
    <type>transmission_interface/SimpleTransmission</type>
    <joint name="rf_haa_joint">
      <hardwareInterface>EffortJointInterface</hardwareInterface>
    </joint>
    <actuator name="rf_haa_motor">
      <hardwareInterface>EffortJointInterface</hardwareInterface>
      <mechanicalReduction>1</mechanicalReduction>
    </actuator>
  </transmission>
  <!-- Upper leg -->
  <transmission name="rf_hfe_trans">
    <type>transmission_interface/SimpleTransmission</type>
    <joint name="rf_hfe_joint">
      <hardwareInterface>EffortJointInterface</hardwareInterface>
    </joint>
    <actuator name="rf_hfe_motor">
      <hardwareInterface>EffortJointInterface</hardwareInterface>
      <mechanicalReduction>1</mechanicalReduction>
    </actuator>
  </transmission>
  <!-- Lower leg -->
  <transmission name="rf_kfe_trans">
    <type>transmission_interface/SimpleTransmission</type>
    <joint name="rf_kfe_joint">
      <hardwareInterface>EffortJointInterface</hardwareInterface>
    </joint>
    <actuator name="rf_kfe_motor">
      <hardwareInterface>EffortJointInterface</hardwareInterface>
      <mechanicalReduction>1</mechanicalReduction>
    </actuator>
  </transmission>
  <gazebo reference="rf_haa_joint">
    <provideFeedback>true</provideFeedback>
  </gazebo>
  <gazebo reference="rf_kfe_joint">
    <provideFeedback>true</provideFeedback>
  </gazebo>
  <gazebo reference="rf_hfe_joint">
    <provideFeedback>true</provideFeedback>
  </gazebo>
  <gazebo reference="rf_upperleg">
    <kp>100000000.0</kp>
    <kd>100.0</kd>
    <mu1>1.5</mu1>
    <mu2>1.5</mu2>
    <maxVel>1.0</maxVel>
    <minDepth>0.00</minDepth>
  </gazebo>
  <gazebo reference="rf_lowerleg">
    <kp>100000000.0</kp>
    <kd>100.0</kd>
    <mu1>1.5</mu1>
    <mu2>1.5</mu2>
    <maxVel>1.0</maxVel>
    <maxContacts>1</maxContacts>
    <minDepth>0.00</minDepth>
    <sensor name="rf_shin_contact_sensor" type="contact">
      <always_on>true</always_on>
      <update_rate>250.0</update_rate>
      <contact>
        <collision>rf_lowerleg_collision</collision>
      </contact>
      <plugin filename="libgazebo_ros_bumper.so" name="rf_shin_bumper">
        <bumperTopicName>/rf_shin_sensor</bumperTopicName>
      </plugin>
    </sensor>
  </gazebo>
  <gazebo reference="rf_foot">
    <kp>1000000.0</kp>
    <kd>100.0</kd>
    <mu1>1.0</mu1>
    <mu2>1.0</mu2>
    <maxVel>1.0</maxVel>
    <maxContacts>1</maxContacts>
    <!-- contact sensor -->
    <sensor name="rf_foot_contact_sensor" type="contact">
      <always_on>true</always_on>
      <update_rate>250.0</update_rate>
      <contact>
        <collision>rf_foot_collision</collision>
      </contact>
      <plugin filename="libgazebo_ros_bumper.so" name="rf_foot_bumper">
        <bumperTopicName>/rf_foot_grf</bumperTopicName>
        <frameName>base_link</frameName>
      </plugin>
    </sensor>
    <material>Gazebo/Black</material>
  </gazebo>
  <!-- Joints -->
  <!-- HAA joint -->
  <joint name="lh_haa_joint" type="revolute">
    <origin rpy="3.14159265359 1.57079632679 0" xyz="-0.4435 0.139 0"/>
    <parent link="trunk"/>
    <child link="lh_hipassembly"/>
    <axis xyz="0 0 1"/>
    <dynamics damping="0.1" friction="0"/>
    <limit effort="173.0" lower="-0.733038285838" upper="0.401425727959" velocity="12.0"/>
    <safety_controller k_position="50" k_velocity="10" soft_lower_limit="-0.733038285838" soft_upper_limit="0.401425727959"/>
  </joint>
  <!-- HFE joint -->
  <joint name="lh_hfe_joint" type="revolute">
    <origin rpy="1.57079632679 0 0" xyz="0 -0.117 0"/>
    <parent link="lh_hipassembly"/>
    <child link="lh_upperleg"/>
    <axis xyz="0 0 1"/>
    <dynamics damping="0.1" friction="0"/>
    <limit effort="208" lower="-2.35619449019" upper="2.35619449019" velocity="12.0"/>
    <safety_controller k_position="50" k_velocity="10" soft_lower_limit="-2.35619449019" soft_upper_limit="2.35619449019"/>
  </joint>
  <!-- KFE joint -->
  <joint name="lh_kfe_joint" type="revolute">
    <origin rpy="0 0 0" xyz="0.36 0 0"/>
    <parent link="lh_upperleg"/>
    <child link="lh_lowerleg"/>
    <axis xyz="0 0 1"/>
    <dynamics damping="0.1" friction="0"/>
    <limit effort="249" lower="-2.87979326579" upper="-0.558505360638" velocity="12.0"/>
    <safety_controller k_position="50.0" k_velocity="10.0" soft_lower_limit="-2.87979326579" soft_upper_limit="-0.558505360638"/>
  </joint>
  <!-- Foot joint -->
  <joint name="lh_foot_joint" type="fixed">
    <origin rpy="1.57079632679 0 -1.57079632679" xyz="0.38 0 0"/>
    <parent link="lh_lowerleg"/>
    <child link="lh_foot"/>
  </joint>
  <!-- Links -->
  <!-- Hip assembly link -->
  <link name="lh_hipassembly">
    <inertial>
      <origin xyz="-0.010027 -0.010608 0.003644"/>
      <mass value="4.973275"/>
      <inertia ixx="0.011231" ixy="-0.000592" ixz="0.000225" iyy="0.015768" iyz="0.000224" izz="0.016863"/>
    </inertial>
    <visual>
      <origin rpy="0 -1.57079632679 -1.57079632679" xyz="0 -0.046 0"/>
      <geometry>
         --&gt;
				
        <cylinder length="0.117" radius="0.0444"/>
      </geometry>
    </visual>
  </link>
  <!-- Upper leg link -->
  <link name="lh_upperleg">
    <inertial>
      <origin xyz="0.107987 -0.011459 -0.002121"/>
      <mass value="5.877927"/>
      <inertia ixx="0.016432" ixy="0.001863" ixz="0.003897" iyy="0.075737" iyz="-0.00024" izz="0.079267"/>
    </inertial>
    <visual>
      <origin rpy="0 0 0" xyz="0 0 0"/>
      <geometry>
        <mesh filename="package://hyqreal_description/meshes/leg/upperleg.dae" scale="0.001 0.001 0.001"/>
      </geometry>
    </visual>
    <collision>
      <origin rpy="0 0 0" xyz="0 0 0"/>
      <geometry>
        <mesh filename="package://hyqreal_description/meshes/leg/upperleg.dae" scale="0.001 0.001 0.001"/>
      </geometry>
    </collision>
  </link>
  <!-- Lower leg link -->
  <link name="lh_lowerleg">
    <inertial>
      <origin xyz="0.149302 -0.003801 -0.000624"/>
      <mass value="1.291954"/>
      <inertia ixx="0.001088" ixy="-0.000572" ixz="0.000118" iyy="0.029215" iyz="0.00046" izz="0.029772"/>
    </inertial>
    <visual>
      <origin rpy="0 0 0" xyz="0 0 0"/>
      <geometry>
        <mesh filename="package://hyqreal_description/meshes/leg/lowerleg.dae" scale="0.001 0.001 0.001"/>
      </geometry>
      <material name="white"/>
    </visual>
    <collision>
      <origin rpy="0 0 0" xyz="0 0 0"/>
      <geometry>
        <mesh filename="package://hyqreal_description/meshes/leg/lowerleg_decimated.dae" scale="0.001 0.001 0.001"/>
      </geometry>
    </collision>
  </link>
  <!-- Foot link -->
  <link name="lh_foot">
    <visual>
      <origin rpy="0.0 0.0 0.0" xyz="0.0 0.0 0.0"/>
      <geometry>
        <sphere radius="0.032"/>
      </geometry>
      <material name="black"/>
    </visual>
    <collision>
      <origin rpy="0 0 0" xyz="0 0 0"/>
      <geometry>
        <sphere radius="0.032"/>
      </geometry>
    </collision>
  </link>
  <!-- Hip assembly -->
  <transmission name="lh_haa_trans">
    <type>transmission_interface/SimpleTransmission</type>
    <joint name="lh_haa_joint">
      <hardwareInterface>EffortJointInterface</hardwareInterface>
    </joint>
    <actuator name="lh_haa_motor">
      <hardwareInterface>EffortJointInterface</hardwareInterface>
      <mechanicalReduction>1</mechanicalReduction>
    </actuator>
  </transmission>
  <!-- Upper leg -->
  <transmission name="lh_hfe_trans">
    <type>transmission_interface/SimpleTransmission</type>
    <joint name="lh_hfe_joint">
      <hardwareInterface>EffortJointInterface</hardwareInterface>
    </joint>
    <actuator name="lh_hfe_motor">
      <hardwareInterface>EffortJointInterface</hardwareInterface>
      <mechanicalReduction>1</mechanicalReduction>
    </actuator>
  </transmission>
  <!-- Lower leg -->
  <transmission name="lh_kfe_trans">
    <type>transmission_interface/SimpleTransmission</type>
    <joint name="lh_kfe_joint">
      <hardwareInterface>EffortJointInterface</hardwareInterface>
    </joint>
    <actuator name="lh_kfe_motor">
      <hardwareInterface>EffortJointInterface</hardwareInterface>
      <mechanicalReduction>1</mechanicalReduction>
    </actuator>
  </transmission>
  <gazebo reference="lh_haa_joint">
    <provideFeedback>true</provideFeedback>
  </gazebo>
  <gazebo reference="lh_kfe_joint">
    <provideFeedback>true</provideFeedback>
  </gazebo>
  <gazebo reference="lh_hfe_joint">
    <provideFeedback>true</provideFeedback>
  </gazebo>
  <gazebo reference="lh_upperleg">
    <kp>100000000.0</kp>
    <kd>100.0</kd>
    <mu1>1.5</mu1>
    <mu2>1.5</mu2>
    <maxVel>1.0</maxVel>
    <minDepth>0.00</minDepth>
  </gazebo>
  <gazebo reference="lh_lowerleg">
    <kp>100000000.0</kp>
    <kd>100.0</kd>
    <mu1>1.5</mu1>
    <mu2>1.5</mu2>
    <maxVel>1.0</maxVel>
    <maxContacts>1</maxContacts>
    <minDepth>0.00</minDepth>
    <sensor name="lh_shin_contact_sensor" type="contact">
      <always_on>true</always_on>
      <update_rate>250.0</update_rate>
      <contact>
        <collision>lh_lowerleg_collision</collision>
      </contact>
      <plugin filename="libgazebo_ros_bumper.so" name="lh_shin_bumper">
        <bumperTopicName>/lh_shin_sensor</bumperTopicName>
      </plugin>
    </sensor>
  </gazebo>
  <gazebo reference="lh_foot">
    <kp>1000000.0</kp>
    <kd>100.0</kd>
    <mu1>1.0</mu1>
    <mu2>1.0</mu2>
    <maxVel>1.0</maxVel>
    <maxContacts>1</maxContacts>
    <!-- contact sensor -->
    <sensor name="lh_foot_contact_sensor" type="contact">
      <always_on>true</always_on>
      <update_rate>250.0</update_rate>
      <contact>
        <collision>lh_foot_collision</collision>
      </contact>
      <plugin filename="libgazebo_ros_bumper.so" name="lh_foot_bumper">
        <bumperTopicName>/lh_foot_grf</bumperTopicName>
        <frameName>base_link</frameName>
      </plugin>
    </sensor>
    <material>Gazebo/Black</material>
  </gazebo>
  <!-- Joints -->
  <!-- HAA joint -->
  <joint name="rh_haa_joint" type="revolute">
    <origin rpy="0 1.57079632679 0" xyz="-0.4435 -0.139 0"/>
    <parent link="trunk"/>
    <child link="rh_hipassembly"/>
    <axis xyz="0 0 1"/>
    <dynamics damping="0.1" friction="0"/>
    <limit effort="173.0" lower="-0.733038285838" upper="0.401425727959" velocity="12.0"/>
    <safety_controller k_position="50" k_velocity="10" soft_lower_limit="-0.733038285838" soft_upper_limit="0.401425727959"/>
  </joint>
  <!-- HFE joint -->
  <joint name="rh_hfe_joint" type="revolute">
    <origin rpy="-1.57079632679 0 0" xyz="0 -0.117 0"/>
    <parent link="rh_hipassembly"/>
    <child link="rh_upperleg"/>
    <axis xyz="0 0 1"/>
    <dynamics damping="0.1" friction="0"/>
    <limit effort="208" lower="-2.35619449019" upper="2.35619449019" velocity="12.0"/>
    <safety_controller k_position="50" k_velocity="10" soft_lower_limit="-2.35619449019" soft_upper_limit="2.35619449019"/>
  </joint>
  <!-- KFE joint -->
  <joint name="rh_kfe_joint" type="revolute">
    <origin rpy="0 0 0" xyz="0.36 0 0"/>
    <parent link="rh_upperleg"/>
    <child link="rh_lowerleg"/>
    <axis xyz="0 0 1"/>
    <dynamics damping="0.1" friction="0"/>
    <limit effort="249" lower="-2.87979326579" upper="-0.558505360638" velocity="12.0"/>
    <safety_controller k_position="50.0" k_velocity="10.0" soft_lower_limit="-2.87979326579" soft_upper_limit="-0.558505360638"/>
  </joint>
  <!-- Foot joint -->
  <joint name="rh_foot_joint" type="fixed">
    <origin rpy="1.57079632679 0 -1.57079632679" xyz="0.38 0 0"/>
    <parent link="rh_lowerleg"/>
    <child link="rh_foot"/>
  </joint>
  <!-- Links -->
  <!-- Hip assembly link -->
  <link name="rh_hipassembly">
    <inertial>
      <origin xyz="-0.010027 -0.010608 0.003644"/>
      <mass value="4.973275"/>
      <inertia ixx="0.011231" ixy="-0.000592" ixz="0.000225" iyy="0.015768" iyz="0.000224" izz="0.016863"/>
    </inertial>
    <visual>
      <origin rpy="0 -1.57079632679 -1.57079632679" xyz="0 -0.046 0"/>
      <geometry>
         --&gt;
				
        <cylinder length="0.117" radius="0.0444"/>
      </geometry>
    </visual>
  </link>
  <!-- Upper leg link -->
  <link name="rh_upperleg">
    <inertial>
      <origin xyz="0.107987 -0.011459 0.002121"/>
      <mass value="5.877927"/>
      <inertia ixx="0.016432" ixy="0.001863" ixz="-0.003897" iyy="0.075737" iyz="0.00024" izz="0.079267"/>
    </inertial>
    <visual>
      <origin rpy="0 0 0" xyz="0 0 0"/>
      <geometry>
        <mesh filename="package://hyqreal_description/meshes/leg/upperleg.dae" scale="0.001 0.001 0.001"/>
      </geometry>
    </visual>
    <collision>
      <origin rpy="0 0 0" xyz="0 0 0"/>
      <geometry>
        <mesh filename="package://hyqreal_description/meshes/leg/upperleg.dae" scale="0.001 0.001 0.001"/>
      </geometry>
    </collision>
  </link>
  <!-- Lower leg link -->
  <link name="rh_lowerleg">
    <inertial>
      <origin xyz="0.149302 -0.003801 -0.000624"/>
      <mass value="1.291954"/>
      <inertia ixx="0.001088" ixy="-0.000572" ixz="0.000118" iyy="0.029215" iyz="0.00046" izz="0.029772"/>
    </inertial>
    <visual>
      <origin rpy="0 0 0" xyz="0 0 0"/>
      <geometry>
        <mesh filename="package://hyqreal_description/meshes/leg/lowerleg.dae" scale="0.001 0.001 0.001"/>
      </geometry>
      <material name="white"/>
    </visual>
    <collision>
      <origin rpy="0 0 0" xyz="0 0 0"/>
      <geometry>
        <mesh filename="package://hyqreal_description/meshes/leg/lowerleg_decimated.dae" scale="0.001 0.001 0.001"/>
      </geometry>
    </collision>
  </link>
  <!-- Foot link -->
  <link name="rh_foot">
    <visual>
      <origin rpy="0.0 0.0 0.0" xyz="0.0 0.0 0.0"/>
      <geometry>
        <sphere radius="0.032"/>
      </geometry>
      <material name="black"/>
    </visual>
    <collision>
      <origin rpy="0 0 0" xyz="0 0 0"/>
      <geometry>
        <sphere radius="0.032"/>
      </geometry>
    </collision>
  </link>
  <!-- Hip assembly -->
  <transmission name="rh_haa_trans">
    <type>transmission_interface/SimpleTransmission</type>
    <joint name="rh_haa_joint">
      <hardwareInterface>EffortJointInterface</hardwareInterface>
    </joint>
    <actuator name="rh_haa_motor">
      <hardwareInterface>EffortJointInterface</hardwareInterface>
      <mechanicalReduction>1</mechanicalReduction>
    </actuator>
  </transmission>
  <!-- Upper leg -->
  <transmission name="rh_hfe_trans">
    <type>transmission_interface/SimpleTransmission</type>
    <joint name="rh_hfe_joint">
      <hardwareInterface>EffortJointInterface</hardwareInterface>
    </joint>
    <actuator name="rh_hfe_motor">
      <hardwareInterface>EffortJointInterface</hardwareInterface>
      <mechanicalReduction>1</mechanicalReduction>
    </actuator>
  </transmission>
  <!-- Lower leg -->
  <transmission name="rh_kfe_trans">
    <type>transmission_interface/SimpleTransmission</type>
    <joint name="rh_kfe_joint">
      <hardwareInterface>EffortJointInterface</hardwareInterface>
    </joint>
    <actuator name="rh_kfe_motor">
      <hardwareInterface>EffortJointInterface</hardwareInterface>
      <mechanicalReduction>1</mechanicalReduction>
    </actuator>
  </transmission>
  <gazebo reference="rh_haa_joint">
    <provideFeedback>true</provideFeedback>
  </gazebo>
  <gazebo reference="rh_kfe_joint">
    <provideFeedback>true</provideFeedback>
  </gazebo>
  <gazebo reference="rh_hfe_joint">
    <provideFeedback>true</provideFeedback>
  </gazebo>
  <gazebo reference="rh_upperleg">
    <kp>100000000.0</kp>
    <kd>100.0</kd>
    <mu1>1.5</mu1>
    <mu2>1.5</mu2>
    <maxVel>1.0</maxVel>
    <minDepth>0.00</minDepth>
  </gazebo>
  <gazebo reference="rh_lowerleg">
    <kp>100000000.0</kp>
    <kd>100.0</kd>
    <mu1>1.5</mu1>
    <mu2>1.5</mu2>
    <maxVel>1.0</maxVel>
    <maxContacts>1</maxContacts>
    <minDepth>0.00</minDepth>
    <sensor name="rh_shin_contact_sensor" type="contact">
      <always_on>true</always_on>
      <update_rate>250.0</update_rate>
      <contact>
        <collision>rh_lowerleg_collision</collision>
      </contact>
      <plugin filename="libgazebo_ros_bumper.so" name="rh_shin_bumper">
        <bumperTopicName>/rh_shin_sensor</bumperTopicName>
      </plugin>
    </sensor>
  </gazebo>
  <gazebo reference="rh_foot">
    <kp>1000000.0</kp>
    <kd>100.0</kd>
    <mu1>1.0</mu1>
    <mu2>1.0</mu2>
    <maxVel>1.0</maxVel>
    <maxContacts>1</maxContacts>
    <!-- contact sensor -->
    <sensor name="rh_foot_contact_sensor" type="contact">
      <always_on>true</always_on>
      <update_rate>250.0</update_rate>
      <contact>
        <collision>rh_foot_collision</collision>
      </contact>
      <plugin filename="libgazebo_ros_bumper.so" name="rh_foot_bumper">
        <bumperTopicName>/rh_foot_grf</bumperTopicName>
        <frameName>base_link</frameName>
      </plugin>
    </sensor>
    <material>Gazebo/Black</material>
  </gazebo>
  <joint name="joint_base_robots" type="fixed">
    <parent link="base_link"/>
    <child link="_teleop_link0"/>
    <origin rpy="0 0 0" xyz="0.59 0 0"/>
  </joint>
  <!-- 
  ROS urdf definition of the TELEOP robot by Istituto Italiano di Tecnologia
  
  DO NOT INCLUDE THIS FILE DIRECTLY! USE teleop_robot.urdf.xacro INSTEAD!

  Author: Enrico Mingo

  Inertial matrix has to be in CoM frame (URDF specs)
-->
  <!-- 
  ROS urdf definition of the TELEOP robot by Istituto Italiano di Tecnologia
  
  DO NOT INCLUDE THIS FILE DIRECTLY! USE teleop_robot.urdf.xacro INSTEAD!

  Author: Enrico Mingo Hoffman

  Inertial matrix has to be in CoM frame (URDF specs)

-->
  <material name="grey">
    <color rgba="0.5 0.5 0.5 1"/>
  </material>
  <material name="red">
    <color rgba="1.0 0.0 0.0 1"/>
  </material>
  <!-- DYNAMICS PARAMETERS NEEDS TO BE CHEKED! -->
  <link name="_teleop_link0">
    <inertial>
      <origin rpy="0 0 0" xyz="0.0 0.0 0.0"/>
      <mass value="1.5"/>
      <inertia ixx="0.001" ixy="0.0" ixz="0.0" iyy="0.001" iyz="0.0" izz="0.001"/>
    </inertial>
    <visual>
      <origin rpy="1.57079632679 0 0" xyz="0 0 0"/>
      <geometry name="_teleop_link0_visual">
        <mesh filename="package://teleop_urdf/meshes/_teleop_link0.stl" scale="0.001 0.001 0.001"/>
      </geometry>
      <material name="red"/>
    </visual>
    <collision>
      <origin rpy="1.57079632679 0 0" xyz="0 0 0"/>
      <geometry name="_teleop_link0_collision">
        <mesh filename="package://teleop_urdf/meshes/simple/_teleop_link0.stl" scale="0.001 0.001 0.001"/>
      </geometry>
    </collision>
  </link>
  <link name="_teleop_link1">
    <inertial>
      <origin rpy="0 0 0" xyz="0.0 -0.02 0.05"/>
      <mass value="0.3"/>
      <inertia ixx="0.001" ixy="0.0" ixz="0.0" iyy="0.001" iyz="0.0" izz="0.0008"/>
    </inertial>
    <visual>
      <origin rpy="1.57079632679 0 -1.57079632679" xyz="0 0 0"/>
      <geometry name="_teleop_link1_visual">
        <mesh filename="package://teleop_urdf/meshes/_teleop_link1.stl" scale="0.001 0.001 0.001"/>
      </geometry>
      <material name="red"/>
    </visual>
    <collision>
      <origin rpy="1.57079632679 0 -1.57079632679" xyz="0 0 0"/>
      <geometry name="_teleop_link1_collision">
        <mesh filename="package://teleop_urdf/meshes/simple/_teleop_link1.stl" scale="0.001 0.001 0.001"/>
      </geometry>
    </collision>
  </link>
  <link name="_teleop_link2">
    <inertial>
      <origin rpy="0 0 0" xyz="0.0 0.01 0.18"/>
      <mass value="3.3"/>
      <inertia ixx="0.04" ixy="0.0" ixz="0.0" iyy="0.04" iyz="0.0" izz="0.01"/>
    </inertial>
    <visual>
      <origin rpy="1.57079632679 0 0" xyz="0 0 0"/>
      <geometry name="_teleop_link2_visual">
        <mesh filename="package://teleop_urdf/meshes/_teleop_link2.stl" scale="0.001 0.001 0.001"/>
      </geometry>
      <material name="red"/>
    </visual>
    <collision>
      <origin rpy="1.57079632679 0 0" xyz="0 0 0"/>
      <geometry name="_teleop_link2_collision">
        <mesh filename="package://teleop_urdf/meshes/simple/_teleop_link2.stl" scale="0.001 0.001 0.001"/>
      </geometry>
    </collision>
  </link>
  <link name="_teleop_link3">
    <inertial>
      <origin rpy="0 0 0" xyz="0.0 -0.02 0.05"/>
      <mass value="0.3"/>
      <inertia ixx="0.001" ixy="0.0" ixz="0.0" iyy="0.001" iyz="0.0" izz="0.0008"/>
    </inertial>
    <visual>
      <origin rpy="1.57079632679 0 0" xyz="0 0 0"/>
      <geometry name="_teleop_link3_visual">
        <mesh filename="package://teleop_urdf/meshes/_teleop_link3.stl" scale="0.001 0.001 0.001"/>
      </geometry>
      <material name="red"/>
    </visual>
    <collision>
      <origin rpy="1.57079632679 0 0" xyz="0 0 0"/>
      <geometry name="_teleop_link3_collision">
        <mesh filename="package://teleop_urdf/meshes/simple/_teleop_link3.stl" scale="0.001 0.001 0.001"/>
      </geometry>
    </collision>
  </link>
  <link name="_teleop_link4">
    <inertial>
      <origin rpy="0 0 0" xyz="0.0 0.0 0.1"/>
      <mass value="2.5"/>
      <inertia ixx="0.015" ixy="0.0" ixz="0.0" iyy="0.015" iyz="0.0" izz="0.008"/>
    </inertial>
    <visual>
      <origin rpy="1.57079632679 0 0" xyz="0 0 0"/>
      <geometry name="_teleop_link4_visual">
        <mesh filename="package://teleop_urdf/meshes/_teleop_link4.stl" scale="0.001 0.001 0.001"/>
      </geometry>
      <material name="red"/>
    </visual>
    <collision>
      <origin rpy="1.57079632679 0 0" xyz="0 0 0"/>
      <geometry name="_teleop_link4_collision">
        <mesh filename="package://teleop_urdf/meshes/simple/_teleop_link4.stl" scale="0.001 0.001 0.001"/>
      </geometry>
    </collision>
  </link>
  <link name="_teleop_link5">
    <inertial>
      <origin rpy="0 0 0" xyz="0.0 0.0 0.15"/>
      <mass value="2"/>
      <inertia ixx="0.01" ixy="0.0" ixz="0.0" iyy="0.01" iyz="0.0" izz="0.01"/>
    </inertial>
    <visual>
      <origin rpy="1.57079632679 0 3.14159265359" xyz="0 0 0"/>
      <geometry name="_teleop_link5_visual">
        <mesh filename="package://teleop_urdf/meshes/_teleop_link5.stl" scale="0.001 0.001 0.001"/>
      </geometry>
      <material name="red"/>
    </visual>
    <collision>
      <origin rpy="1.57079632679 0 3.14159265359" xyz="0 0 0"/>
      <geometry name="_teleop_link5_collision">
        <mesh filename="package://teleop_urdf/meshes/simple/_teleop_link5.stl" scale="0.001 0.001 0.001"/>
      </geometry>
    </collision>
  </link>
  <joint name="joint1" type="revolute">
    <parent link="_teleop_link0"/>
    <child link="_teleop_link1"/>
    <origin rpy="0 0 0" xyz="0.0 0 0"/>
    <axis xyz="0 0 1"/>
    <limit effort="55" lower="-1.75" upper="1.75" velocity="11.7"/>
    <dynamics damping="0.03" friction="0"/>
  </joint>
  <joint name="joint2" type="revolute">
    <parent link="_teleop_link1"/>
    <child link="_teleop_link2"/>
    <origin rpy="0 0 0" xyz="0 0 0.1315"/>
    <axis xyz="0 1 0"/>
    <limit effort="147" lower="-2.15" upper="2.15" velocity="5.2"/>
    <dynamics damping="0.03" friction="0"/>
  </joint>
  <joint name="joint3" type="revolute">
    <parent link="_teleop_link2"/>
    <child link="_teleop_link3"/>
    <origin rpy="0 0 0" xyz="0 0 0.365"/>
    <axis xyz="0 1 0"/>
    <limit effort="127" lower="-2.15" upper="2.15" velocity="8.1"/>
    <dynamics damping="0.03" friction="0"/>
  </joint>
  <joint name="joint4" type="revolute">
    <parent link="_teleop_link3"/>
    <child link="_teleop_link4"/>
    <origin rpy="0 0 0" xyz="0 0 0.1"/>
    <axis xyz="0 0 1"/>
    <limit effort="28" lower="-2.79" upper="2.79" velocity="20.4"/>
    <dynamics damping="0.03" friction="0"/>
  </joint>
  <joint name="joint5" type="revolute">
    <parent link="_teleop_link4"/>
    <child link="_teleop_link5"/>
    <origin rpy="0 0 0" xyz="0 0 0.226"/>
    <axis xyz="0 1 0"/>
    <limit effort="28" lower="-1.83" upper="1.83" velocity="20.4"/>
    <dynamics damping="0.03" friction="0"/>
  </joint>
  <link name="TCP"/>
  <joint name="TCP_joint" type="fixed">
    <parent link="_teleop_link5"/>
    <child link="TCP"/>
    <origin rpy="0 0 0" xyz="0 0 0.27"/>
  </joint>
</robot>

